Workbook

Sheet THKP hạng mục
A1: BẢNG TỔNG HỢP DỰ TOÁN CHI PHÍ XÂY DỰNG
A2: Tên công trình: XÂY DỰNG NHÀ Ở CHO LỰC LƯỢNG VŨ TRANG CÔNG AN NHÂN DÂN (NHÀ Ở XÃ HỘI CHO CÁN BỘ, CHIẾN SỸ CÔNG AN) TẠI CÁC Ô ĐẤT CE-ODK3 VÀ C3-ODK4 THUỘC QUY HOẠCH PHÂN KHU ĐÔ THỊ H2-4, PHƯỜNG YÊN SỞ, THÀNH PHỐ HÀ NỘI
A3: Tên hạng mục: THÍ NGHIỆM SIÊU ÂM KIỂM TRA CHẤT LƯỢNG CỌC KHOAN ĐẠI TRÀ
A4: STT | B4: NỘI DUNG CHI PHÍ | D4: CÁCH TÍNH | G4: HỆ SỐ | H4: ="GIÁ TRỊ "&'Công trình'!AM1 -> GIÁ TRỊ (đ) | I4: KÝ HIỆU
A5: I | B5: CHI PHÍ TRỰC TIẾP | D5: VL + NC + M | H5: =H6+H8+H10 -> 8.4309462e+08 | I5: T
A6: 1 | B6: Chi phí Vật liệu | D6: =I7 -> A1 | H6: =H7 -> 3540813.7 | I6: VL
B7: + Theo giá xây dựng tổng hợp | D7: Bảng giá tổng hợp | H7: ='Giá tổng hợp'!I7 -> 3540813.7 | I7: A1
A8: 2 | B8: Chi phí Nhân công | D8: =I9 -> B1 | H8: =H9 -> 683766720 | I8: NC
B9: + Theo giá xây dựng tổng hợp | D9: Bảng giá tổng hợp | H9: ='Giá tổng hợp'!J7 -> 683766720 | I9: B1
A10: 3 | B10: Chi phí Máy thi công | D10: =I11 -> C1 | H10: =H11 -> 1.5578709e+08 | I10: M
B11: + Theo giá xây dựng tổng hợp | D11: Bảng giá tổng hợp | H11: ='Giá tổng hợp'!K7 -> 1.5578709e+08 | I11: C1
A12: ="" | B12: Cộng chi phí trực tiếp
A13: II | B13: CHI PHÍ GIÁN TIẾP | D13: (C + TT) | H13: =SUM(H14:H15) -> 5.2922238e+08 | I13: GT
A14: 1 | B14: Chi phí chung | D14: ="NC x "&HSXL!C$14 -> NC x 70% | G14: =HSXL!C$14 -> 70% | H14: =H8*HSXL!D$14 -> 4.786367e+08 | I14: C
A15: 2 | B15: Chi phí một số công việc không xác định được khối lượng từ thiết kế | D15: ="T x "&HSXL!C$13 -> T x 6% | G15: =HSXL!C$13 -> 6% | H15: =H5*HSXL!D$13 -> 50585677 | I15: TT
A16: III | B16: THU NHẬP CHỊU THUẾ TÍNH TRƯỚC | D16: ="(T+GT) x "&HSXL!C$16 -> (T+GT) x 6% | G16: =HSXL!C$16 -> 6% | H16: =(H5+H13)*HSXL!D$16 -> 82339020 | I16: TL
A17: IV | B17: CHI PHÍ PHỤC VỤ CÔNG TÁC KHẢO SÁT XD | D17: ="" | H17: =H20 -> 72732801 | I17: Cpvks
A18: 1 | B18: Chi phí lập phương án kỹ thuật khảo sát | D18: (T + GT + TL) x 2% | H18: =(H5+H13+H16)*2% -> 29093121 | I18: Cpa
A19: 2 | B19: Chi phí lập báo cáo kết quả khảo sát | D19: (T + GT + TL) x 3% | H19: =(H5+H13+H16)*3% -> 43639681 | I19: Cbc
A20: ="" | B20: Cộng chi phí phục vụ công tác khảo sát | D20: (Cpa + Cbc) | H20: =SUM(H18:H19) -> 72732801 | I20: =""
A21: ="" | B21: Chi phí khảo sát xây dựng trước thuế | D21: (T+GT+TL + Cpvks) | H21: =H5+H13+H16+H20 -> 1.5273888e+09 | I21: G
A22: V | B22: THUẾ GIÁ TRỊ GIA TĂNG | D22: ="G x "&HSXL!C$17 -> G x 10% | E22: =G22 -> 0.1 | G22: =HSXL!D$17 -> 0.1 | H22: =E22*H21 -> 1.5273888e+08 | I22: GTGT
A23: ="" | B23: Chi phí khảo sát sau thuế | D23: G + GTGT | H23: =H21+H22 -> 1.6801277e+09 | I23: Gks
A24: VI | B24: Chi phí nhà tạm để ở và điều hành thi công | D24: ="Gks x "&HSXL!C$18 -> Gks x 2% | E24: =G24 -> 0.02 | G24: =HSXL!D$18 -> 0.02 | H24: =E24*H23 -> 33602554 | I24: LT
A25: VII | B25: Chi phí Dự phòng | D25: Gks x 0% | H25: =E25*H23 -> 0 | I25: Gdp
A26: ="" | B26: Chi phí khảo sát xây dựng | D26: ="" | H26: =ROUND(H23+H24+H25,0) -> 1713730264 | I26: =""
B27: LÀM TRÒN | H27: =ROUND(H26,-3) -> 1713730000
A28: Bằng chữ: Một tỷ bảy trăm mười ba triệu bảy trăm ba mươi nghìn đồng chẵn./.
A29: =A1 -> BẢNG TỔNG HỢP DỰ TOÁN CHI PHÍ XÂY DỰNG
A30: =A2 -> Tên công trình: XÂY DỰNG NHÀ Ở CHO LỰC LƯỢNG VŨ TRANG CÔNG AN NHÂN DÂN (NHÀ Ở XÃ HỘI CHO CÁN BỘ, CHIẾN SỸ CÔNG AN) TẠI CÁC Ô ĐẤT CE-ODK3 VÀ C3-ODK4 THUỘC QUY HOẠCH PHÂN KHU ĐÔ THỊ H2-4, PHƯỜNG YÊN SỞ, THÀNH PHỐ HÀ NỘI
A31: Tên hạng mục: KHOAN KIỂM TRA XỬ LÝ ĐÁY CỌC KHOAN NHỒI ĐẠI TRÀ
A32: =A4 -> STT | B32: =B4 -> NỘI DUNG CHI PHÍ | C32: =C4 -> 0 | D32: =D4 -> CÁCH TÍNH | E32: =E4 -> 0 | F32: =F4 -> 0 | G32: =G4 -> HỆ SỐ | H32: =H4 -> GIÁ TRỊ (đ) | I32: =I4 -> KÝ HIỆU
A33: I | B33: CHI PHÍ TRỰC TIẾP | D33: VL + NC + M | H33: =H34+H36+H38 -> 1.4472041e+08 | I33: T
A34: 1 | B34: Chi phí Vật liệu | D34: =I35 -> A1 | H34: =H35 -> 1213540.9 | I34: VL
B35: + Theo giá xây dựng tổng hợp | D35: Bảng giá tổng hợp | H35: ='Giá tổng hợp'!I14 -> 1213540.9 | I35: A1
A36: 2 | B36: Chi phí Nhân công | D36: =I37 -> B1 | H36: =H37 -> 95403000 | I36: NC
B37: + Theo giá xây dựng tổng hợp | D37: Bảng giá tổng hợp | H37: ='Giá tổng hợp'!J14 -> 95403000 | I37: B1
A38: 3 | B38: Chi phí Máy thi công | D38: =I39 -> C1 | H38: =H39 -> 48103871 | I38: M
B39: + Theo giá xây dựng tổng hợp | D39: Bảng giá tổng hợp | H39: ='Giá tổng hợp'!K14 -> 48103871 | I39: C1
A40: ="" | B40: Cộng chi phí trực tiếp
...

Sheet Giá tổng hợp
A1: GIÁ XÂY DỰNG TỔNG HỢP HẠNG MỤC CÔNG TRÌNH
A2: ='Công trình'!A2 -> CÔNG TRÌNH : XÂY DỰNG NHÀ Ở CHO LỰC LƯỢNG VŨ TRANG CÔNG AN NHÂN DÂN (NHÀ Ở XÃ HỘI CHO CÁN BỘ, CHIẾN SỸ CÔNG AN) TẠI CÁC Ô ĐẤT CE-ODK3 VÀ C3-ODK4 THUỘC QUY HOẠCH PHÂN KHU ĐÔ THỊ H2-4, PHƯỜNG YÊN SỞ, THÀNH PHỐ HÀ NỘI
A3: ='Công trình'!F6 -> THÍ NGHIỆM SIÊU ÂM KIỂM TRA CHẤT LƯỢNG CỌC KHOAN ĐẠI TRÀ
A4: STT | B4: Mã số | C4: Tên công tác | D4: Đơn vị | E4: Khối lượng | F4: ="Đơn giá "&'Công trình'!AM1 -> Đơn giá (đ) | I4: ="Thành tiền "&'Công trình'!AM1 -> Thành tiền (đ) | L4: ="Tổng cộng "&'Công trình'!AM1 -> Tổng cộng (đ)
F5: Vật liệu | G5: Nhân công | H5: Máy T.C | I5: Vật liệu | J5: Nhân công | K5: Máy T.C
A6: ='Công trình'!A7 -> 1 | B6: ='Công trình'!E7 -> CE.12910 | C6: ='Công trình'!F7 -> Thí nghiệm kiểm tra chất lượng cọc bê tông bằng phương pháp siêu âm | D6: ='Công trình'!G7 -> mặt cắt/lần TN | E6: ='Công trình'!P7 -> 1008 | F6: ='Đơn giá chi tiết'!H$6 -> 3512.712 | G6: ='Đơn giá chi tiết'!H$11 -> 678340 | H6: ='Đơn giá chi tiết'!H$15 -> 154550.68 | I6: =E6*F6 -> 3540813.7 | J6: =E6*G6 -> 683766720 | K6: =E6*H6 -> 1.5578709e+08 | L6: =(I6+J6+K6) -> 8.4309462e+08 | M6: 1
C7: TỔNG HẠNG MỤC | I7: =SUM(I6:I6) -> 3540813.7 | J7: =SUM(J6:J6) -> 683766720 | K7: =SUM(K6:K6) -> 1.5578709e+08 | L7: =SUM(L6:L6) -> 8.4309462e+08
A8: =A1 -> GIÁ XÂY DỰNG TỔNG HỢP HẠNG MỤC CÔNG TRÌNH
A9: ='Công trình'!A2 -> CÔNG TRÌNH : XÂY DỰNG NHÀ Ở CHO LỰC LƯỢNG VŨ TRANG CÔNG AN NHÂN DÂN (NHÀ Ở XÃ HỘI CHO CÁN BỘ, CHIẾN SỸ CÔNG AN) TẠI CÁC Ô ĐẤT CE-ODK3 VÀ C3-ODK4 THUỘC QUY HOẠCH PHÂN KHU ĐÔ THỊ H2-4, PHƯỜNG YÊN SỞ, THÀNH PHỐ HÀ NỘI
A10: ='Công trình'!F11 -> KHOAN KIỂM TRA XỬ LÝ ĐÁY CỌC KHOAN NHỒI ĐẠI TRÀ
A11: =A4 -> STT | B11: =B4 -> Mã số | C11: =C4 -> Tên công tác | D11: =D4 -> Đơn vị | E11: =E4 -> Khối lượng | F11: =F4 -> Đơn giá (đ) | G11: =G4 -> 0 | H11: =H4 -> 0 | ... L11: =L4 -> Tổng cộng (đ)
A12: =A5 -> 0 | B12: =B5 -> 0 | C12: =C5 -> 0 | D12: =D5 -> 0 | E12: =E5 -> 0 | F12: =F5 -> Vật liệu | G12: =G5 -> Nhân công | H12: =H5 -> Máy T.C | ... L12: =L5 -> 0
A13: ='Công trình'!A12 -> 1 | B13: ='Công trình'!E12 -> AL.55120 | C13: ='Công trình'!F12 -> Khoan kiểm tra, xử lý đáy cọc khoan nhồi, đường kính lỗ khoan > 80mm | D13: ='Công trình'!G12 -> cọc | E13: ='Công trình'!P12 -> 22 | F13: ='Đơn giá chi tiết'!H$24 -> 55160.95 | G13: ='Đơn giá chi tiết'!H$28 -> 4336500 | H13: ='Đơn giá chi tiết'!H$30 -> 2186539.6 | I13: =E13*F13 -> 1213540.9 | J13: =E13*G13 -> 95403000 | K13: =E13*H13 -> 48103871 | L13: =(I13+J13+K13) -> 1.4472041e+08 | M13: 1
C14: TỔNG HẠNG MỤC | I14: =SUM(I13:I13) -> 1213540.9 | J14: =SUM(J13:J13) -> 95403000 | K14: =SUM(K13:K13) -> 48103871 | L14: =SUM(L13:L13) -> 1.4472041e+08
C15: TỔNG CÔNG TRÌNH
C16: LÀM TRÒN | I16: =ROUND(I15,-3) -> 0 | J16: =ROUND(J15,-3) -> 0 | K16: =ROUND(K15,-3) -> 0 | L16: =ROUND(L15,-3) -> 0

Sheet Công trình
A1: BẢNG DỰ TOÁN HẠNG MỤC CÔNG TRÌNH | AM1: (đ)
A2: CÔNG TRÌNH : XÂY DỰNG NHÀ Ở CHO LỰC LƯỢNG VŨ TRANG CÔNG AN NHÂN DÂN (NHÀ Ở XÃ HỘI CHO CÁN BỘ, CHIẾN SỸ CÔNG AN) TẠI CÁC Ô ĐẤT CE-ODK3 VÀ C3-ODK4 THUỘC QUY HOẠCH PHÂN KHU ĐÔ THỊ H2-4, PHƯỜNG YÊN SỞ, THÀNH PHỐ HÀ NỘI
A3: THÍ NGHIỆM SIÊU ÂM KIỂM TRA CHẤT LƯỢNG CỌC KHOAN ĐẠI TRÀ
A4: STT | B4: Ký hiệu bản vẽ | C4: Mã hiệu định mức | D4: Mã hiệu vữa | E4: Mã hiệu công tác | F4: Danh mục công tác/ Diễn giải KL | G4: Đơn vị tính | H4: Số C.K | I4: Kích thước | L4: Hệ số phụ | M4: Tổng dài | N4: D.tích (M2) | O4: K.L C.Kiện | P4: Khối lượng | Q4: ="Đơn giá "&'Công trình'!AM1 -> Đơn giá (đ) | U4: ="Thành tiền "&'Công trình'!AM1 -> Thành tiền (đ) | Y4: Hệ số điều chỉnh | AB4: Ghi chú, Nguồn gốc xuất xứ | AC4: Dữ liệu đã dùng | AE4: Hao phí định mức | AH4: Hệ số định mức | AK4: Thời điểm thi công | AM4: Tỉnh TP / Chuyên ngành
I5: Dài | J5: Rộng | K5: Cao | Q5: Vật liệu | R5: V.L phụ | S5: Nhân công | T5: Máy T.C | U5: Vật liệu | V5: V.L phụ | W5: Nhân công | X5: Máy thi công | Y5: V.L | Z5: N.C | AA5: Máy | AC5: Đơn giá | AD5: Giá máy | AE5: V.L | AF5: N.C | AG5: Máy | AH5: V.L | AI5: N.C | AJ5: Máy | AK5: Bắt đầu | AL5: Kết thúc
E6: HM | F6: THÍ NGHIỆM SIÊU ÂM KIỂM TRA CHẤT LƯỢNG CỌC KHOAN ĐẠI TRÀ | O6: 3
A7: 1 | C7: CE.12910 | E7: CE.12910 | F7: Thí nghiệm kiểm tra chất lượng cọc bê tông bằng phương pháp siêu âm | G7: mặt cắt/lần TN | M7: =ROUND(SUM(M8:M9),3) -> 1008 | N7: =ROUND(SUM(N8:N9),3) -> 1008 | P7: =ROUND(SUM(O7:O9),3) -> 1008 | U7: =P7*Q7 -> 0 | V7: =P7*R7 -> 0 | W7: =P7*S7 -> 0 | X7: =P7*T7 -> 0 | AC7: Định mức 38/2026/TT-BXD - Phần KS | AD7: GM38_2026 | AE7: A28.0325~Thước thép 5m~cái~0.04~0.04~0~13636~0~1~1~0~14726.9~ThuocThep~Tham khảo bộ đơn giá số 378/2023 Hà Nội~0žA28.0324~Thước thép 42m~cái~0.04~0.04~0~70000~0~1~1~0~75600~ThuocThep~Tham khảo bộ đơn giá số 378/2023 Hà Nội~0žZ999~Vật liệu khác~%~5~5~0~33.4544~0~1~1~0~0~~~0 | AF7: NKS~Kỹ sư~công~0.46~0.46~0~435000~0~1~1~0~0~KS~Được tính toán, rồi Link từ sheet Nhân công sang~0žN3~Nhân công nhóm 3~công~1.12~1.12~0~427000~0~1~1~0~0~N3~Được tính toán, rồi Link từ sheet Nhân công sang~0 | AG7: M202.0008~Bộ thiết bị siêu âm~ca~0.32~0.32~0~478189~0~1~1~0~0~M709~Được tính toán, rồi Link từ sheet Máy sang~0žM999~Máy khác~%~1~1~0~1530.2048~0~1~1~0~0~~~0 | AM7: DinhMucBoXD
F8: Cọc D1500 | H8: =11+81+3+24+4+28 -> 151 | I8: 6 | M8: =ROUND(PRODUCT(H8:I8),3) -> 906 | N8: =ROUND(PRODUCT(H8:J8),3) -> 906 | O8: =ROUND(PRODUCT(H8:L8),3) -> 906
F9: Cọc D1000 | H9: 34 | I9: 3 | M9: =ROUND(PRODUCT(H9:I9),3) -> 102 | N9: =ROUND(PRODUCT(H9:J9),3) -> 102 | O9: =ROUND(PRODUCT(H9:L9),3) -> 102
E10: THM | F10: Tổng cộng: THÍ NGHIỆM SIÊU ÂM KIỂM TRA CHẤT LƯỢNG CỌC KHOAN ĐẠI TRÀ | U10: =SUM(U7:U9) -> 0 | V10: =SUM(V7:V9) -> 0 | W10: =SUM(W7:W9) -> 0 | X10: =SUM(X7:X9) -> 0
E11: HM | F11: KHOAN KIỂM TRA XỬ LÝ ĐÁY CỌC KHOAN NHỒI ĐẠI TRÀ
A12: 1 | C12: AL.55120 | E12: AL.55120 | F12: Khoan kiểm tra, xử lý đáy cọc khoan nhồi, đường kính lỗ khoan > 80mm | G12: cọc | P12: =ROUND(SUM(O12:O14),3) -> 22 | U12: =P12*Q12 -> 0 | V12: =P12*R12 -> 0 | W12: =P12*S12 -> 0 | X12: =P12*T12 -> 0 | AC12: Định mức 38/2026/TT-BXD - Phần XD | AD12: GM38_2026 | AE12: A24.0247~Cần khoan L=1,5m~cái~0.026~0.026~0~200000~0~1~1~0~216000~CanKhoan1.5m~Tham khảo bộ đơn giá số 378/2023 Hà Nội~0žA24.0492~Mũi khoan d>80mm~cái~0.065~0.065~0~768630~0~1~1~0~830120.4~MuiKhoan>80~Tham khảo bộ đơn giá số 378/2023 Hà Nội~0 | AF12: N2~Nhân công nhóm 2~công~10.5~10.5~0~413000~0~1~1~0~0~N2~Được tính toán, rồi Link từ sheet Nhân công sang~0 | AG12: M107.0202~Máy khoan xoay đập tự hành F105mm~ca~0.45~0.45~0~2219339~0~1~1~0~0~M466~Được tính toán, rồi Link từ sheet Máy sang~0žM108.0307~Máy nén khí diezel 660 m3/h~ca~0.45~0.45~0~2408258~0~1~1~0~0~M405~Được tính toán, rồi Link từ sheet Máy sang~0žM999~Máy khác~%~5~5~0~20824.1865~0~1~1~0~0~~~0 | AM12: DinhMucBoXD
F13: Cọc D1500 | H13: =11+3+4 -> 18 | O13: =ROUND(PRODUCT(H13:L13),3) -> 18
F14: Cọc D1000 | H14: 4 | O14: =ROUND(PRODUCT(H14:L14),3) -> 4
E15: THM | F15: Tổng cộng: KHOAN KIỂM TRA XỬ LÝ ĐÁY CỌC KHOAN NHỒI ĐẠI TRÀ | U15: =SUM(U12:U14) -> 0 | V15: =SUM(V12:V14) -> 0 | W15: =SUM(W12:W14) -> 0 | X15: =SUM(X12:X14) -> 0

Sheet Giá tháng
A1: BẢNG GIÁ THÔNG BÁO CÔNG TRÌNH
A2: ='Công trình'!A2 -> CÔNG TRÌNH : XÂY DỰNG NHÀ Ở CHO LỰC LƯỢNG VŨ TRANG CÔNG AN NHÂN DÂN (NHÀ Ở XÃ HỘI CHO CÁN BỘ, CHIẾN SỸ CÔNG AN) TẠI CÁC Ô ĐẤT CE-ODK3 VÀ C3-ODK4 THUỘC QUY HOẠCH PHÂN KHU ĐÔ THỊ H2-4, PHƯỜNG YÊN SỞ, THÀNH PHỐ HÀ NỘI
A4: STT | B4: Mã số | C4: Tên vật tư | D4: Đơn vị | E4: ="Giá gốc "&'Công trình'!AM1 -> Giá gốc (đ) | F4: ="Giá tháng "&'Công trình'!AM1 -> Giá tháng (đ) | G4: Hệ số | H4: Chính | I4: ="Giá sau VAT "&'Công trình'!AM1 -> Giá sau VAT (đ) | J4: Mã chuẩn | K4: Ghi chú, Nguồn gốc xuất xứ
A5: I | C5: VẬT LIỆU
A6: 1 | B6: A24.0247 | C6: Cần khoan L=1,5m | D6: cái | E6: 0 | F6: 200000 | G6: 1 | H6: TRUE | I6: 216000 | J6: CanKhoan1.5m | K6: Tham khảo bộ đơn giá số 378/2023 Hà Nội
A7: 2 | B7: A24.0492 | C7: Mũi khoan d>80mm | D7: cái | E7: 0 | F7: 768630 | G7: 1 | H7: TRUE | I7: 830120.4 | J7: MuiKhoan>80 | K7: Tham khảo bộ đơn giá số 378/2023 Hà Nội
A8: 3 | B8: A28.0324 | C8: Thước thép 42m | D8: cái | E8: 0 | F8: 70000 | G8: 1 | H8: TRUE | I8: 75600 | J8: ThuocThep | K8: Tham khảo bộ đơn giá số 378/2023 Hà Nội
A9: 4 | B9: A28.0325 | C9: Thước thép 5m | D9: cái | E9: 0 | F9: 13636 | G9: 1 | H9: TRUE | I9: 14726.9 | J9: ThuocThep | K9: Tham khảo bộ đơn giá số 378/2023 Hà Nội
A10: II | C10: NHÂN CÔNG
A11: 1 | B11: NKS | C11: Kỹ sư | D11: công | E11: 0 | F11: ='Nhân công'!T8 -> 435000 | G11: 1 | H11: TRUE | J11: KS | K11: Được tính toán, rồi Link từ sheet Nhân công sang
A12: 2 | B12: N2 | C12: Nhân công nhóm 2 | D12: công | E12: 0 | F12: ='Nhân công'!T9 -> 413000 | G12: 1 | H12: TRUE | J12: N2 | K12: Được tính toán, rồi Link từ sheet Nhân công sang
A13: 3 | B13: N3 | C13: Nhân công nhóm 3 | D13: công | E13: 0 | F13: ='Nhân công'!T10 -> 427000 | G13: 1 | H13: TRUE | J13: N3 | K13: Được tính toán, rồi Link từ sheet Nhân công sang
A14: III | C14: MÁY THI CÔNG
A15: 1 | B15: M202.0008 | C15: Bộ thiết bị siêu âm | D15: ca | E15: 0 | F15: =Máy!K6 -> 478189 | G15: 1 | H15: TRUE | J15: M709 | K15: Được tính toán, rồi Link từ sheet Máy sang
A16: 2 | B16: M107.0202 | C16: Máy khoan xoay đập tự hành F105mm | D16: ca | E16: 0 | F16: =Máy!K11 -> 2219339 | G16: 1 | H16: TRUE | J16: M466 | K16: Được tính toán, rồi Link từ sheet Máy sang
A17: 3 | B17: M108.0307 | C17: Máy nén khí diezel 660 m3/h | D17: ca | E17: 0 | F17: =Máy!K19 -> 2408258 | G17: 1 | H17: TRUE | J17: M405 | K17: Được tính toán, rồi Link từ sheet Máy sang

Sheet Đầu vào
A1: DỮ LIỆU ĐẦU VÀO TÍNH NHÂN CÔNG, CA MÁY
A2: ='Công trình'!A2 -> CÔNG TRÌNH : XÂY DỰNG NHÀ Ở CHO LỰC LƯỢNG VŨ TRANG CÔNG AN NHÂN DÂN (NHÀ Ở XÃ HỘI CHO CÁN BỘ, CHIẾN SỸ CÔNG AN) TẠI CÁC Ô ĐẤT CE-ODK3 VÀ C3-ODK4 THUỘC QUY HOẠCH PHÂN KHU ĐÔ THỊ H2-4, PHƯỜNG YÊN SỞ, THÀNH PHỐ HÀ NỘI
A3: BẢNG 1. MỨC LƯƠNG, SỐ NGÀY LÀM VIỆC
A4: STT | B4: Tên, loại dữ liệu | D4: Giá trị
B5: Mức lương tối thiểu chung (đồng/tháng) | D5: 0
A6: 1 | B6: Mức lương đầu vào LNC (đồng/tháng) | D6: 0
A7: 2 | B7: Số ngày làm việc (ngày/tháng) | D7: 26
A8: 3 | B8: Hệ số điều chỉnh nhân công | D8: 1
A9: BẢNG 2. TỶ LỆ CÁC KHOẢN PHỤ CẤP
A10: STT | B10: Loại phụ cấp | D10: Tỷ lệ
A11: 1 | B11: Phụ cấp lưu động | D11: 0
A12: 2 | B12: Không ổn định sản xuất | D12: 0
A13: 3 | B13: Lương phụ nghỉ lễ, tết hoặc nghỉ phép ... | D13: 0
A14: 4 | B14: Chi phí có thể khoán trực tiếp cho người lao động | D14: 0
A15: 5 | B15: Phụ cấp khu vực | D15: 0
A16: 6 | B16: Phụ cấp độc hại | D16: 0
A17: 7 | B17: Phụ cấp thu hút | D17: 0
A18: 8 | B18: Phụ cấp trách nhiệm | D18: 0
A19: 9 | B19: Phụ cấp bảo hiểm | D19: 0
A20: 10 | B20: Phụ cấp vùng sâu, vùng xa, khó khăn, đắt đỏ | D20: 0
A21: BẢNG 3. ĐƠN GIÁ NHIÊN LIỆU, ĐIỆN (TRƯỚC THUẾ VAT)
A22: STT | B22: Loại nhiên liệu, năng lượng | C22: Đơn vị | D22: ="Đơn giá "&'Công trình'!AM1 -> Đơn giá (đ)
A23: 1 | B23: Diezel | C23: Lít | D23: 28080
A24: 2 | B24: Mazut | C24: Lít | D24: 15781.8
A25: 3 | B25: Điện | C25: kwh | D25: 2204.0655 | E25: Giá điện theo: Quyết định 1279/QĐ-BCT ngày 09/05/2025
A26: 4 | B26: Xăng | C26: Lít | D26: 21760 | E26: Giá nhiên liệu theo: Công bố của Petrolimex ngày 27/08/2026
A27: BẢNG 4. HỆ SỐ NHIÊN LIỆU PHỤ
A28: STT | B28: Loại động cơ | D28: Hệ số
A29: 1 | B29: Động cơ Diezel | D29: 1.03
A30: 2 | B30: Động cơ Mazut | D30: 1
A31: 3 | B31: Động cơ Điện | D31: 1.05
A32: 4 | B32: Động cơ Xăng | D32: 1.02
A33: BẢNG 5. THU HỒI KHI THANH LÝ
A34: STT | B34: Loại nhiên liệu, năng lượng | D34: Giá trị
A35: 1 | B35: Thu hồi thanh lý khi nguyên giá từ (triệu đồng) | D35: 30
A36: 2 | B36: Tỷ lệ thu hồi khi thanh lý | D36: 0.1
A37: BẢNG 6. LÀM TRÒN SỐ HỌC
A38: STT | B38: Đối tượng làm tròn | D38: Làm tròn
A39: 1 | B39: Giá | D39: 1 | E39: =D39 -> 1
A40: 2 | B40: Đơn giá Nhân công, Lương thợ lái máy | D40: 0 | E40: =D40 -> 0
...

Sheet Nhân công
A1: BẢNG TÍNH ĐƠN GIÁ NHÂN CÔNG
A2: (Theo HD 14502/SXD-KTXD năm 2026 của TP Hà Nội - Phường Yên Sở.)
A3: ='Công trình'!A2 -> CÔNG TRÌNH : XÂY DỰNG NHÀ Ở CHO LỰC LƯỢNG VŨ TRANG CÔNG AN NHÂN DÂN (NHÀ Ở XÃ HỘI CHO CÁN BỘ, CHIẾN SỸ CÔNG AN) TẠI CÁC Ô ĐẤT CE-ODK3 VÀ C3-ODK4 THUỘC QUY HOẠCH PHÂN KHU ĐÔ THỊ H2-4, PHƯỜNG YÊN SỞ, THÀNH PHỐ HÀ NỘI
A4: ="Đơn vị tính: "&'Công trình'!AM1 -> Đơn vị tính: (đ)
A5: STT | B5: Mã số | C5: Tên nhân công | D5: Đơn vị | E5: Hệ số lương (HCB) | F5: Đơn giá NC bình quân (đ/công) | G5: Hệ số lương bình quân | H5: Lương CB (đ/công) | I5: ="Phụ cấp "&'Công trình'!AM1 -> Phụ cấp (đ) | S5: Hệ số điều chỉnh nhân công | T5: Đơn giá nhân công (đ/công) | U5: Hệ số lương (chưa làm tròn)
I6: ="Lưu động ("&'Đầu vào'!D11*100&"% LTC)" -> Lưu động (0% LTC) | J6: ="Không ổn định S.X ("&'Đầu vào'!D12*100&"% LCB)" -> Không ổn định S.X (0% LCB) | K6: ="Lương phụ nghỉ lễ, tết ("&'Đầu vào'!D13*100&"% LCB)" -> Lương phụ nghỉ lễ, tết (0% LCB) | L6: ="Khoán trực tiếp ("&'Đầu vào'!D14*100&"% LCB)" -> Khoán trực tiếp (0% LCB) | M6: ="Khu vực ("&'Đầu vào'!D15*100&"% LTC)" -> Khu vực (0% LTC) | N6: ="Độc hại ("&'Đầu vào'!D16*100&"% LTC)" -> Độc hại (0% LTC) | O6: ="Thu hút ("&'Đầu vào'!D17*100&"% LCB)" -> Thu hút (0% LCB) | P6: ="Trách nhiệm ("&'Đầu vào'!D18*100&"% LTC)" -> Trách nhiệm (0% LTC) | Q6: ="Bảo hiểm ("&'Đầu vào'!D19*100&"% LCB)" -> Bảo hiểm (0% LCB) | R6: ="Vùng sâu, vùng xa ("&'Đầu vào'!D20*100&"% LCB)" -> Vùng sâu, vùng xa (0% LCB)
I7: ='Đầu vào'!D11 -> 0 | J7: ='Đầu vào'!D12 -> 0 | K7: ='Đầu vào'!D13 -> 0 | L7: ='Đầu vào'!D14 -> 0 | M7: ='Đầu vào'!D15 -> 0 | N7: ='Đầu vào'!D16 -> 0 | O7: ='Đầu vào'!D17 -> 0 | P7: ='Đầu vào'!D18 -> 0 | Q7: ='Đầu vào'!D19 -> 0 | R7: ='Đầu vào'!D20 -> 0
A8: 1 | B8: ='Giá tháng'!B11 -> NKS | C8: ='Giá tháng'!C11 -> Kỹ sư | D8: ='Giá tháng'!D11 -> công | H8: 435000 | J8: =J7*H8 -> 0 | K8: =K7*H8 -> 0 | L8: =L7*H8 -> 0 | O8: =O7*H8 -> 0 | Q8: =Q7*H8 -> 0 | R8: =R7*H8 -> 0 | T8: =ROUND(SUM(H8:R8),'Đầu vào'!D40) -> 435000
A9: 2 | B9: ='Giá tháng'!B12 -> N2 | C9: ='Giá tháng'!C12 -> Nhân công nhóm 2 | D9: ='Giá tháng'!D12 -> công | H9: 413000 | J9: =J7*H9 -> 0 | K9: =K7*H9 -> 0 | L9: =L7*H9 -> 0 | O9: =O7*H9 -> 0 | Q9: =Q7*H9 -> 0 | R9: =R7*H9 -> 0 | T9: =ROUND(SUM(H9:R9),'Đầu vào'!D40) -> 413000
A10: 3 | B10: ='Giá tháng'!B13 -> N3 | C10: ='Giá tháng'!C13 -> Nhân công nhóm 3 | D10: ='Giá tháng'!D13 -> công | H10: 427000 | J10: =J7*H10 -> 0 | K10: =K7*H10 -> 0 | L10: =L7*H10 -> 0 | O10: =O7*H10 -> 0 | Q10: =Q7*H10 -> 0 | R10: =R7*H10 -> 0 | T10: =ROUND(SUM(H10:R10),'Đầu vào'!D40) -> 427000

Sheet Máy
A1: BẢNG TÍNH ĐƠN GIÁ CA MÁY
A2: (Theo Thông tư 37/2026/TT-BXD, HD 14502/SXD-KTXD năm 2026 của TP Hà Nội - Phường Yên Sở.)
A3: ='Công trình'!A2 -> CÔNG TRÌNH : XÂY DỰNG NHÀ Ở CHO LỰC LƯỢNG VŨ TRANG CÔNG AN NHÂN DÂN (NHÀ Ở XÃ HỘI CHO CÁN BỘ, CHIẾN SỸ CÔNG AN) TẠI CÁC Ô ĐẤT CE-ODK3 VÀ C3-ODK4 THUỘC QUY HOẠCH PHÂN KHU ĐÔ THỊ H2-4, PHƯỜNG YÊN SỞ, THÀNH PHỐ HÀ NỘI
A4: ="Đơn vị tính: "&'Công trình'!AM1 -> Đơn vị tính: (đ)
A5: STT | B5: Mã số | C5: Tên máy và thiết bị thi công / Diễn giải | D5: Đơn vị | E5: ="Nguyên giá "&'Công trình'!AM1 -> Nguyên giá (đ) | F5: Số ca / 1 năm | G5: Định mức | H5: ="Đơn giá "&'Công trình'!AM1 -> Đơn giá (đ) | I5: Hệ số | J5: Số ngày / tháng | K5: ="Chi phí "&'Công trình'!AM1 -> Chi phí (đ)
A6: 1 | B6: ='Giá tháng'!B15 -> M202.0008 | C6: ='Giá tháng'!C15 -> Bộ thiết bị siêu âm | D6: ='Giá tháng'!D15 -> ca | E6: 573827000 | F6: 180 | K6: =ROUND(K7,'Đầu vào'!D41) -> 478189
C7: * Khấu hao, Sửa chữa và Chi phí khác: | K7: =SUM(K8:K10) -> 478189.17
C8: - Khấu hao | G8: 0.1 | H8: =E6 -> 573827000 | I8: =IF(E6>='Đầu vào'!D35*10^6,1-'Đầu vào'!D36,1) -> 0.9 | K8: =G8*H8*I8/F6 -> 286913.5
C9: - Sửa chữa | G9: 0.02 | H9: =E6 -> 573827000 | K9: =G9*H9/F6 -> 63758.556
C10: - Chi phí khác | G10: 0.04 | H10: =E6 -> 573827000 | K10: =G10*H10/F6 -> 127517.11
A11: 2 | B11: ='Giá tháng'!B16 -> M107.0202 | C11: ='Giá tháng'!C16 -> Máy khoan xoay đập tự hành F105mm | D11: ='Giá tháng'!D16 -> ca | E11: 1376725000 | F11: 270 | K11: =ROUND(K12+K15,'Đầu vào'!D41) -> 2219339
C12: * Nhân công vận hành máy: | K12: =G13*K13 -> 914000
C13: - Nhân công vận hành | G13: 2 | K13: =ROUND(SUM(K14:K14),'Đầu vào'!E40) -> 457000
C14: Lương cơ bản | H14: 457000 | K14: =H14 -> 457000
C15: * Khấu hao, Sửa chữa và Chi phí khác: | K15: =SUM(K16:K18) -> 1305339.3
C16: - Khấu hao | G16: 0.17 | H16: =E11 -> 1376725000 | I16: =IF(E11>='Đầu vào'!D35*10^6,1-'Đầu vào'!D36,1) -> 0.9 | K16: =G16*H16*I16/F11 -> 780144.17
C17: - Sửa chữa | G17: 0.053 | H17: =E11 -> 1376725000 | K17: =G17*H17/F11 -> 270246.02
C18: - Chi phí khác | G18: 0.05 | H18: =E11 -> 1376725000 | K18: =G18*H18/F11 -> 254949.07
A19: 3 | B19: ='Giá tháng'!B17 -> M108.0307 | C19: ='Giá tháng'!C17 -> Máy nén khí diezel 660 m3/h | D19: ='Giá tháng'!D17 -> ca | E19: 478552000 | F19: 180 | K19: =ROUND(K20+K22+K25,'Đầu vào'!D41) -> 2408258
C20: * Nhiên liệu, năng lượng: | K20: =SUM(K21:K21) -> 1446120
C21: =" - "&'Đầu vào'!B23 -> - Diezel | D21: ='Đầu vào'!C23 -> Lít | G21: 50 | H21: ='Đầu vào'!D23 -> 28080 | I21: ='Đầu vào'!D29 -> 1.03 | K21: =G21*H21*I21 -> 1446120
C22: * Nhân công vận hành máy: | K22: =G23*K23 -> 457000
C23: - Nhân công vận hành | G23: 1 | K23: =ROUND(SUM(K24:K24),'Đầu vào'!E40) -> 457000
C24: Lương cơ bản | H24: 457000 | K24: =H24 -> 457000
C25: * Khấu hao, Sửa chữa và Chi phí khác: | K25: =SUM(K26:K28) -> 505138.22
C26: - Khấu hao | G26: 0.1 | H26: =E19 -> 478552000 | I26: =IF(E19>='Đầu vào'!D35*10^6,1-'Đầu vào'!D36,1) -> 0.9 | K26: =G26*H26*I26/F19 -> 239276
C27: - Sửa chữa | G27: 0.05 | H27: =E19 -> 478552000 | K27: =G27*H27/F19 -> 132931.11
C28: - Chi phí khác | G28: 0.05 | H28: =E19 -> 478552000 | K28: =G28*H28/F19 -> 132931.11

Sheet HaoPhiVatTu
A1: HAO PHÍ VẬT LIỆU, NHÂN CÔNG, MÁY CHO CÁC CÔNG TÁC
A2: ='Công trình'!A2 -> CÔNG TRÌNH : XÂY DỰNG NHÀ Ở CHO LỰC LƯỢNG VŨ TRANG CÔNG AN NHÂN DÂN (NHÀ Ở XÃ HỘI CHO CÁN BỘ, CHIẾN SỸ CÔNG AN) TẠI CÁC Ô ĐẤT CE-ODK3 VÀ C3-ODK4 THUỘC QUY HOẠCH PHÂN KHU ĐÔ THỊ H2-4, PHƯỜNG YÊN SỞ, THÀNH PHỐ HÀ NỘI | M2: VL khác, Máy khác
A3: ='Công trình'!F6 -> THÍ NGHIỆM SIÊU ÂM KIỂM TRA CHẤT LƯỢNG CỌC KHOAN ĐẠI TRÀ | M3: VLK gốc | N3: MK gốc | O3: VLK HT | P3: MK HT | Q3: Cước VC | R3: Cước bộ | S3: So sánh
A4: STT | B4: Mã hiệu | C4: Tên công tác / vật tư | D4: Đơn vị | E4: Khối lượng | F4: Định mức hao phí | G4: Hệ số | H4: Khối lượng hao phí | M4: =SUM(M6:M16) -> 0 | N4: =SUM(N6:N16) -> 0 | O4: =SUM(O6:O16) -> 168610.18 | P4: =SUM(P6:P16) -> 1542446.4
A6: ='Công trình'!A7 -> 1 | B6: ='Công trình'!E7 -> CE.12910 | C6: ='Công trình'!F7 -> Thí nghiệm kiểm tra chất lượng cọc bê tông bằng phương pháp siêu âm | D6: ='Công trình'!G7 -> mặt cắt/lần TN | E6: ='Công trình'!P7 -> 1008
C7: a) Vật liệu
B8: ='Giá tháng'!B9 -> A28.0325 | C8: ='Giá tháng'!C9 -> Thước thép 5m | D8: ='Giá tháng'!D9 -> cái | F8: 0.04 | G8: ='Giá tháng'!G9 -> 1 | H8: =E6*F8*G8 -> 40.32 | S8: 101
B9: ='Giá tháng'!B8 -> A28.0324 | C9: ='Giá tháng'!C8 -> Thước thép 42m | D9: ='Giá tháng'!D8 -> cái | F9: 0.04 | G9: ='Giá tháng'!G8 -> 1 | H9: =E6*F9*G9 -> 40.32 | S9: 100
B10: Z999 | C10: Vật liệu khác | D10: % | F10: 5 | M10: =E6*F10*(F8*'Giá tháng'!E9*'Giá tháng'!G9+F9*'Giá tháng'!E8*'Giá tháng'!G8)/100 -> 0 | O10: =E6*F10*(F8*('Giá tháng'!F9+Q8+R8)*'Giá tháng'!G9+F9*('Giá tháng'!F8+Q9+R9)*'Giá tháng'!G8)/100 -> 168610.18
C11: b) Nhân công
B12: ='Giá tháng'!B11 -> NKS | C12: ='Giá tháng'!C11 -> Kỹ sư | D12: ='Giá tháng'!D11 -> công | F12: 0.46 | G12: ='Giá tháng'!G11 -> 1 | H12: =E6*F12*G12 -> 463.68 | S12: 200
B13: ='Giá tháng'!B13 -> N3 | C13: ='Giá tháng'!C13 -> Nhân công nhóm 3 | D13: ='Giá tháng'!D13 -> công | F13: 1.12 | G13: ='Giá tháng'!G13 -> 1 | H13: =E6*F13*G13 -> 1128.96 | S13: 201
C14: c) Máy thi công
B15: ='Giá tháng'!B15 -> M202.0008 | C15: ='Giá tháng'!C15 -> Bộ thiết bị siêu âm | D15: ='Giá tháng'!D15 -> ca | F15: 0.32 | G15: ='Giá tháng'!G15 -> 1 | H15: =E6*F15*G15 -> 322.56 | S15: 300
B16: M999 | C16: Máy khác | D16: % | F16: 1 | N16: =E6*F16*(F15*'Giá tháng'!E15*'Giá tháng'!G15)/100 -> 0 | P16: =E6*F16*(F15*'Giá tháng'!F15*'Giá tháng'!G15)/100 -> 1542446.4
A17: =A1 -> HAO PHÍ VẬT LIỆU, NHÂN CÔNG, MÁY CHO CÁC CÔNG TÁC
A18: ='Công trình'!A2 -> CÔNG TRÌNH : XÂY DỰNG NHÀ Ở CHO LỰC LƯỢNG VŨ TRANG CÔNG AN NHÂN DÂN (NHÀ Ở XÃ HỘI CHO CÁN BỘ, CHIẾN SỸ CÔNG AN) TẠI CÁC Ô ĐẤT CE-ODK3 VÀ C3-ODK4 THUỘC QUY HOẠCH PHÂN KHU ĐÔ THỊ H2-4, PHƯỜNG YÊN SỞ, THÀNH PHỐ HÀ NỘI | M18: =M2 -> VL khác, Máy khác
A19: ='Công trình'!F11 -> KHOAN KIỂM TRA XỬ LÝ ĐÁY CỌC KHOAN NHỒI ĐẠI TRÀ | M19: =M3 -> VLK gốc | N19: =N3 -> MK gốc | O19: =O3 -> VLK HT | P19: =P3 -> MK HT | S19: =S3 -> So sánh
A20: =A4 -> STT | B20: =B4 -> Mã hiệu | C20: =C4 -> Tên công tác / vật tư | D20: =D4 -> Đơn vị | E20: =E4 -> Khối lượng | F20: =F4 -> Định mức hao phí | G20: =G4 -> Hệ số | H20: =H4 -> Khối lượng hao phí | N20: =SUM(N22:N31) -> 0 | P20: =SUM(P22:P31) -> 2290660.5
A21: =A5 -> 0 | B21: =B5 -> 0 | C21: =C5 -> 0 | D21: =D5 -> 0 | E21: =E5 -> 0 | F21: =F5 -> 0 | G21: =G5 -> 0 | H21: =H5 -> 0
A22: ='Công trình'!A12 -> 1 | B22: ='Công trình'!E12 -> AL.55120 | C22: ='Công trình'!F12 -> Khoan kiểm tra, xử lý đáy cọc khoan nhồi, đường kính lỗ khoan > 80mm | D22: ='Công trình'!G12 -> cọc | E22: ='Công trình'!P12 -> 22
C23: a) Vật liệu
B24: ='Giá tháng'!B6 -> A24.0247 | C24: ='Giá tháng'!C6 -> Cần khoan L=1,5m | D24: ='Giá tháng'!D6 -> cái | F24: 0.026 | G24: ='Giá tháng'!G6 -> 1 | H24: =E22*F24*G24 -> 0.572 | S24: 110
B25: ='Giá tháng'!B7 -> A24.0492 | C25: ='Giá tháng'!C7 -> Mũi khoan d>80mm | D25: ='Giá tháng'!D7 -> cái | F25: 0.065 | G25: ='Giá tháng'!G7 -> 1 | H25: =E22*F25*G25 -> 1.43 | S25: 111
C26: b) Nhân công
B27: ='Giá tháng'!B12 -> N2 | C27: ='Giá tháng'!C12 -> Nhân công nhóm 2 | D27: ='Giá tháng'!D12 -> công | F27: 10.5 | G27: ='Giá tháng'!G12 -> 1 | H27: =E22*F27*G27 -> 231 | S27: 210
C28: c) Máy thi công
B29: ='Giá tháng'!B16 -> M107.0202 | C29: ='Giá tháng'!C16 -> Máy khoan xoay đập tự hành F105mm | D29: ='Giá tháng'!D16 -> ca | F29: 0.45 | G29: ='Giá tháng'!G16 -> 1 | H29: =E22*F29*G29 -> 9.9 | S29: 310
B30: ='Giá tháng'!B17 -> M108.0307 | C30: ='Giá tháng'!C17 -> Máy nén khí diezel 660 m3/h | D30: ='Giá tháng'!D17 -> ca | F30: 0.45 | G30: ='Giá tháng'!G17 -> 1 | H30: =E22*F30*G30 -> 9.9 | S30: 311
B31: M999 | C31: Máy khác | D31: % | F31: 5 | N31: =E22*F31*(F29*'Giá tháng'!E16*'Giá tháng'!G16+F30*'Giá tháng'!E17*'Giá tháng'!G17)/100 -> 0 | P31: =E22*F31*(F29*'Giá tháng'!F16*'Giá tháng'!G16+F30*'Giá tháng'!F17*'Giá tháng'!G17)/100 -> 2290660.5

Sheet Tổng hợp VT
A1: BẢNG TỔNG HỢP VẬT TƯ VÀ CHÊNH LỆCH GIÁ
A2: ='Công trình'!A2 -> CÔNG TRÌNH : XÂY DỰNG NHÀ Ở CHO LỰC LƯỢNG VŨ TRANG CÔNG AN NHÂN DÂN (NHÀ Ở XÃ HỘI CHO CÁN BỘ, CHIẾN SỸ CÔNG AN) TẠI CÁC Ô ĐẤT CE-ODK3 VÀ C3-ODK4 THUỘC QUY HOẠCH PHÂN KHU ĐÔ THỊ H2-4, PHƯỜNG YÊN SỞ, THÀNH PHỐ HÀ NỘI
A3: ='Công trình'!F6 -> THÍ NGHIỆM SIÊU ÂM KIỂM TRA CHẤT LƯỢNG CỌC KHOAN ĐẠI TRÀ
A4: STT | B4: Mã số | C4: Tên vật tư | D4: Đơn vị | E4: Khối lượng | F4: ="Giá gốc "&'Công trình'!AM1 -> Giá gốc (đ) | G4: ="Thành tiền "&'Công trình'!AM1 -> Thành tiền (đ) | H4: ="Giá T.B "&'Công trình'!AM1 -> Giá T.B (đ) | I4: ="Thành tiền "&'Công trình'!AM1 -> Thành tiền (đ) | J4: Hệ số | K4: ="Giá T.B x H.S "&'Công trình'!AM1 -> Giá T.B x H.S (đ) | L4: ="Thành tiền "&'Công trình'!AM1 -> Thành tiền (đ) | M4: ="Cước V.C Bù NL, lương "&'Công trình'!AM1 -> Cước V.C Bù NL, lương (đ) | N4: ="Thành tiền "&'Công trình'!AM1 -> Thành tiền (đ) | O4: ="Giá H.T "&'Công trình'!AM1 -> Giá H.T (đ) | P4: ="Thành tiền "&'Công trình'!AM1 -> Thành tiền (đ) | Q4: ="Chênh lệch "&'Công trình'!AM1 -> Chênh lệch (đ) | R4: ="Tổng chênh "&'Công trình'!AM1 -> Tổng chênh (đ) | S4: Ghi chú, Nguồn gốc xuất xứ | T4: Cước ôtô Cước sông | U4: Cước bộ
A5: I | C5: VẬT LIỆU
A6: 1 | B6: ='Giá tháng'!B8 -> A28.0324 | C6: ='Giá tháng'!C8 -> Thước thép 42m | D6: ='Giá tháng'!D8 -> cái | E6: =SUMIF(HaoPhiVatTu!S6:S16,100,HaoPhiVatTu!H6:H16) -> 40.32 | F6: ='Giá tháng'!E8 -> 0 | G6: =E6*F6 -> 0 | H6: ='Giá tháng'!F8 -> 70000 | I6: =E6*H6 -> 2822400 | J6: 1 | K6: =H6*J6 -> 70000 | L6: =E6*K6 -> 2822400 | M6: =T6+U6 -> 0 | N6: =E6*M6 -> 0 | O6: =H6+M6 -> 70000 | P6: =E6*O6 -> 2822400 | Q6: =O6-F6 -> 70000 | R6: =P6-G6 -> 2822400 | S6: ='Giá tháng'!K8 -> Tham khảo bộ đơn giá số 378/2023 Hà Nội
A7: 2 | B7: ='Giá tháng'!B9 -> A28.0325 | C7: ='Giá tháng'!C9 -> Thước thép 5m | D7: ='Giá tháng'!D9 -> cái | E7: =SUMIF(HaoPhiVatTu!S6:S16,101,HaoPhiVatTu!H6:H16) -> 40.32 | F7: ='Giá tháng'!E9 -> 0 | G7: =E7*F7 -> 0 | H7: ='Giá tháng'!F9 -> 13636 | I7: =E7*H7 -> 549803.52 | J7: 1 | K7: =H7*J7 -> 13636 | L7: =E7*K7 -> 549803.52 | M7: =T7+U7 -> 0 | N7: =E7*M7 -> 0 | O7: =H7+M7 -> 13636 | P7: =E7*O7 -> 549803.52 | Q7: =O7-F7 -> 13636 | R7: =P7-G7 -> 549803.52 | S7: ='Giá tháng'!K9 -> Tham khảo bộ đơn giá số 378/2023 Hà Nội
A8: 3 | B8: Z999 | C8: Vật liệu khác | D8: % | G8: =HaoPhiVatTu!M4 -> 0 | P8: =HaoPhiVatTu!O4 -> 168610.18 | R8: =P8-G8 -> 168610.18
C9: TỔNG VẬT LIỆU | G9: =SUM(G6:G8) -> 0 | I9: =SUM(I6:I8) -> 3372203.5 | L9: =SUM(L6:L8) -> 3372203.5 | N9: =SUM(N6:N8) -> 0 | P9: =SUM(P6:P8) -> 3540813.7 | R9: =SUM(R6:R8) -> 3540813.7
A10: II | C10: NHÂN CÔNG
A11: 1 | B11: ='Giá tháng'!B11 -> NKS | C11: ='Giá tháng'!C11 -> Kỹ sư | D11: ='Giá tháng'!D11 -> công | E11: =SUMIF(HaoPhiVatTu!S6:S16,200,HaoPhiVatTu!H6:H16) -> 463.68 | F11: ='Giá tháng'!E11 -> 0 | G11: =E11*F11 -> 0 | H11: ='Giá tháng'!F11 -> 435000 | I11: =E11*H11 -> 201700800 | J11: 1 | K11: =H11*J11 -> 435000 | L11: =E11*K11 -> 201700800 | O11: =H11 -> 435000 | P11: =E11*O11 -> 201700800 | Q11: =O11-F11 -> 435000 | R11: =P11-G11 -> 201700800 | S11: ='Giá tháng'!K11 -> Được tính toán, rồi Link từ sheet Nhân công sang
A12: 2 | B12: ='Giá tháng'!B13 -> N3 | C12: ='Giá tháng'!C13 -> Nhân công nhóm 3 | D12: ='Giá tháng'!D13 -> công | E12: =SUMIF(HaoPhiVatTu!S6:S16,201,HaoPhiVatTu!H6:H16) -> 1128.96 | F12: ='Giá tháng'!E13 -> 0 | G12: =E12*F12 -> 0 | H12: ='Giá tháng'!F13 -> 427000 | I12: =E12*H12 -> 482065920 | J12: 1 | K12: =H12*J12 -> 427000 | L12: =E12*K12 -> 482065920 | O12: =H12 -> 427000 | P12: =E12*O12 -> 482065920 | Q12: =O12-F12 -> 427000 | R12: =P12-G12 -> 482065920 | S12: ='Giá tháng'!K13 -> Được tính toán, rồi Link từ sheet Nhân công sang
C13: TỔNG NHÂN CÔNG | G13: =SUM(G11:G12) -> 0 | I13: =SUM(I11:I12) -> 683766720 | L13: =SUM(L11:L12) -> 683766720 | N13: =SUM(N11:N12) -> 0 | P13: =SUM(P11:P12) -> 683766720 | R13: =SUM(R11:R12) -> 683766720
A14: III | C14: MÁY THI CÔNG
A15: 1 | B15: ='Giá tháng'!B15 -> M202.0008 | C15: ='Giá tháng'!C15 -> Bộ thiết bị siêu âm | D15: ='Giá tháng'!D15 -> ca | E15: =SUMIF(HaoPhiVatTu!S6:S16,300,HaoPhiVatTu!H6:H16) -> 322.56 | F15: ='Giá tháng'!E15 -> 0 | G15: =E15*F15 -> 0 | H15: ='Giá tháng'!F15 -> 478189 | I15: =E15*H15 -> 1.5424464e+08 | J15: 1 | K15: =H15*J15 -> 478189 | L15: =E15*K15 -> 1.5424464e+08 | N15: =E15*J15*M15 -> 0 | O15: =H15 -> 478189 | P15: =E15*O15 -> 1.5424464e+08 | Q15: =O15-F15 -> 478189 | R15: =P15-G15 -> 1.5424464e+08 | S15: ='Giá tháng'!K15 -> Được tính toán, rồi Link từ sheet Máy sang
A16: 2 | B16: M999 | C16: Máy khác | D16: % | G16: =HaoPhiVatTu!N4 -> 0 | P16: =HaoPhiVatTu!P4 -> 1542446.4 | R16: =P16-G16 -> 1542446.4
C17: TỔNG MÁY THI CÔNG | G17: =SUM(G15:G16) -> 0 | I17: =SUM(I15:I16) -> 1.5424464e+08 | L17: =SUM(L15:L16) -> 1.5424464e+08 | N17: =SUM(N15:N16) -> 0 | P17: =SUM(P15:P16) -> 1.5578709e+08 | R17: =SUM(R15:R16) -> 1.5578709e+08
A18: =A1 -> BẢNG TỔNG HỢP VẬT TƯ VÀ CHÊNH LỆCH GIÁ
A19: ='Công trình'!A2 -> CÔNG TRÌNH : XÂY DỰNG NHÀ Ở CHO LỰC LƯỢNG VŨ TRANG CÔNG AN NHÂN DÂN (NHÀ Ở XÃ HỘI CHO CÁN BỘ, CHIẾN SỸ CÔNG AN) TẠI CÁC Ô ĐẤT CE-ODK3 VÀ C3-ODK4 THUỘC QUY HOẠCH PHÂN KHU ĐÔ THỊ H2-4, PHƯỜNG YÊN SỞ, THÀNH PHỐ HÀ NỘI
A20: ='Công trình'!F11 -> KHOAN KIỂM TRA XỬ LÝ ĐÁY CỌC KHOAN NHỒI ĐẠI TRÀ
A21: =A4 -> STT | B21: =B4 -> Mã số | C21: =C4 -> Tên vật tư | D21: =D4 -> Đơn vị | E21: =E4 -> Khối lượng | F21: =F4 -> Giá gốc (đ) | G21: =G4 -> Thành tiền (đ) | H21: =H4 -> Giá T.B (đ) | ... S21: =S4 -> Ghi chú, Nguồn gốc xuất xứ
A22: I | C22: VẬT LIỆU
A23: 1 | B23: ='Giá tháng'!B6 -> A24.0247 | C23: ='Giá tháng'!C6 -> Cần khoan L=1,5m | D23: ='Giá tháng'!D6 -> cái | E23: =SUMIF(HaoPhiVatTu!S22:S31,110,HaoPhiVatTu!H22:H31) -> 0.572 | F23: ='Giá tháng'!E6 -> 0 | G23: =E23*F23 -> 0 | H23: ='Giá tháng'!F6 -> 200000 | I23: =E23*H23 -> 114400 | J23: 1 | K23: =H23*J23 -> 200000 | L23: =E23*K23 -> 114400 | M23: =T23+U23 -> 0 | N23: =E23*M23 -> 0 | O23: =H23+M23 -> 200000 | P23: =E23*O23 -> 114400 | Q23: =O23-F23 -> 200000 | R23: =P23-G23 -> 114400 | S23: ='Giá tháng'!K6 -> Tham khảo bộ đơn giá số 378/2023 Hà Nội
A24: 2 | B24: ='Giá tháng'!B7 -> A24.0492 | C24: ='Giá tháng'!C7 -> Mũi khoan d>80mm | D24: ='Giá tháng'!D7 -> cái | E24: =SUMIF(HaoPhiVatTu!S22:S31,111,HaoPhiVatTu!H22:H31) -> 1.43 | F24: ='Giá tháng'!E7 -> 0 | G24: =E24*F24 -> 0 | H24: ='Giá tháng'!F7 -> 768630 | I24: =E24*H24 -> 1099140.9 | J24: 1 | K24: =H24*J24 -> 768630 | L24: =E24*K24 -> 1099140.9 | M24: =T24+U24 -> 0 | N24: =E24*M24 -> 0 | O24: =H24+M24 -> 768630 | P24: =E24*O24 -> 1099140.9 | Q24: =O24-F24 -> 768630 | R24: =P24-G24 -> 1099140.9 | S24: ='Giá tháng'!K7 -> Tham khảo bộ đơn giá số 378/2023 Hà Nội
C25: TỔNG VẬT LIỆU | G25: =SUM(G23:G24) -> 0 | I25: =SUM(I23:I24) -> 1213540.9 | L25: =SUM(L23:L24) -> 1213540.9 | N25: =SUM(N23:N24) -> 0 | P25: =SUM(P23:P24) -> 1213540.9 | R25: =SUM(R23:R24) -> 1213540.9
A26: II | C26: NHÂN CÔNG
A27: 1 | B27: ='Giá tháng'!B12 -> N2 | C27: ='Giá tháng'!C12 -> Nhân công nhóm 2 | D27: ='Giá tháng'!D12 -> công | E27: =SUMIF(HaoPhiVatTu!S22:S31,210,HaoPhiVatTu!H22:H31) -> 231 | F27: ='Giá tháng'!E12 -> 0 | G27: =E27*F27 -> 0 | H27: ='Giá tháng'!F12 -> 413000 | I27: =E27*H27 -> 95403000 | J27: 1 | K27: =H27*J27 -> 413000 | L27: =E27*K27 -> 95403000 | O27: =H27 -> 413000 | P27: =E27*O27 -> 95403000 | Q27: =O27-F27 -> 413000 | R27: =P27-G27 -> 95403000 | S27: ='Giá tháng'!K12 -> Được tính toán, rồi Link từ sheet Nhân công sang
C28: TỔNG NHÂN CÔNG | G28: =SUM(G27:G27) -> 0 | I28: =SUM(I27:I27) -> 95403000 | L28: =SUM(L27:L27) -> 95403000 | N28: =SUM(N27:N27) -> 0 | P28: =SUM(P27:P27) -> 95403000 | R28: =SUM(R27:R27) -> 95403000
A29: III | C29: MÁY THI CÔNG
A30: 1 | B30: ='Giá tháng'!B16 -> M107.0202 | C30: ='Giá tháng'!C16 -> Máy khoan xoay đập tự hành F105mm | D30: ='Giá tháng'!D16 -> ca | E30: =SUMIF(HaoPhiVatTu!S22:S31,310,HaoPhiVatTu!H22:H31) -> 9.9 | F30: ='Giá tháng'!E16 -> 0 | G30: =E30*F30 -> 0 | H30: ='Giá tháng'!F16 -> 2219339 | I30: =E30*H30 -> 21971456 | J30: 1 | K30: =H30*J30 -> 2219339 | L30: =E30*K30 -> 21971456 | N30: =E30*J30*M30 -> 0 | O30: =H30 -> 2219339 | P30: =E30*O30 -> 21971456 | Q30: =O30-F30 -> 2219339 | R30: =P30-G30 -> 21971456 | S30: ='Giá tháng'!K16 -> Được tính toán, rồi Link từ sheet Máy sang
A31: 2 | B31: ='Giá tháng'!B17 -> M108.0307 | C31: ='Giá tháng'!C17 -> Máy nén khí diezel 660 m3/h | D31: ='Giá tháng'!D17 -> ca | E31: =SUMIF(HaoPhiVatTu!S22:S31,311,HaoPhiVatTu!H22:H31) -> 9.9 | F31: ='Giá tháng'!E17 -> 0 | G31: =E31*F31 -> 0 | H31: ='Giá tháng'!F17 -> 2408258 | I31: =E31*H31 -> 23841754 | J31: 1 | K31: =H31*J31 -> 2408258 | L31: =E31*K31 -> 23841754 | N31: =E31*J31*M31 -> 0 | O31: =H31 -> 2408258 | P31: =E31*O31 -> 23841754 | Q31: =O31-F31 -> 2408258 | R31: =P31-G31 -> 23841754 | S31: ='Giá tháng'!K17 -> Được tính toán, rồi Link từ sheet Máy sang
A32: 3 | B32: M999 | C32: Máy khác | D32: % | G32: =HaoPhiVatTu!N20 -> 0 | P32: =HaoPhiVatTu!P20 -> 2290660.5 | R32: =P32-G32 -> 2290660.5
C33: TỔNG MÁY THI CÔNG | G33: =SUM(G30:G32) -> 0 | I33: =SUM(I30:I32) -> 45813210 | L33: =SUM(L30:L32) -> 45813210 | N33: =SUM(N30:N32) -> 0 | P33: =SUM(P30:P32) -> 48103871 | R33: =SUM(R30:R32) -> 48103871

Sheet THVT gộp

Sheet Cước VC

Sheet Cước bộ

Sheet Đơn giá chi tiết
A1: ĐƠN GIÁ XÂY DỰNG CHI TIẾT HẠNG MỤC CÔNG TRÌNH
A2: ='Công trình'!A2 -> CÔNG TRÌNH : XÂY DỰNG NHÀ Ở CHO LỰC LƯỢNG VŨ TRANG CÔNG AN NHÂN DÂN (NHÀ Ở XÃ HỘI CHO CÁN BỘ, CHIẾN SỸ CÔNG AN) TẠI CÁC Ô ĐẤT CE-ODK3 VÀ C3-ODK4 THUỘC QUY HOẠCH PHÂN KHU ĐÔ THỊ H2-4, PHƯỜNG YÊN SỞ, THÀNH PHỐ HÀ NỘI
A3: ='Công trình'!F6 -> THÍ NGHIỆM SIÊU ÂM KIỂM TRA CHẤT LƯỢNG CỌC KHOAN ĐẠI TRÀ
A4: STT | B4: Mã số | C4: Thành phần hao phí | D4: Đơn vị | E4: Định mức | F4: ="Đơn giá "&'Công trình'!AM1 -> Đơn giá (đ) | G4: Hệ số | H4: ="Thành tiền "&'Công trình'!AM1 -> Thành tiền (đ)
A5: ='Công trình'!A7 -> 1 | B5: ='Công trình'!E7 -> CE.12910 | C5: ='Công trình'!F7 -> Thí nghiệm kiểm tra chất lượng cọc bê tông bằng phương pháp siêu âm | D5: ='Công trình'!G7 -> mặt cắt/lần TN | E5: 1
C6: a) Vật liệu | H6: =H10 -> 3512.712
B7: ='Giá tháng'!B$9 -> A28.0325 | C7: ='Giá tháng'!C$9 -> Thước thép 5m | D7: ='Giá tháng'!D$9 -> cái | E7: =HaoPhiVatTu!F$8 -> 0.04 | F7: ='Tổng hợp VT'!O$7 -> 13636 | G7: ='Giá tháng'!G$9 -> 1 | H7: =E7*F7*G7 -> 545.44
B8: ='Giá tháng'!B$8 -> A28.0324 | C8: ='Giá tháng'!C$8 -> Thước thép 42m | D8: ='Giá tháng'!D$8 -> cái | E8: =HaoPhiVatTu!F$9 -> 0.04 | F8: ='Tổng hợp VT'!O$6 -> 70000 | G8: ='Giá tháng'!G$8 -> 1 | H8: =E8*F8*G8 -> 2800
B9: Z999 | C9: Vật liệu khác | D9: % | E9: =HaoPhiVatTu!F$10 -> 5 | F9: =SUM(H7:H8) -> 3345.44 | H9: =E9*F9/100 -> 167.272
C10: Cộng | H10: =SUM(H7:H9) -> 3512.712
C11: b) Nhân công | H11: =H14 -> 678340
B12: ='Giá tháng'!B$11 -> NKS | C12: ='Giá tháng'!C$11 -> Kỹ sư | D12: ='Giá tháng'!D$11 -> công | E12: =HaoPhiVatTu!F$12 -> 0.46 | F12: ='Tổng hợp VT'!O$11 -> 435000 | G12: ='Giá tháng'!G$11 -> 1 | H12: =E12*F12*G12 -> 200100
B13: ='Giá tháng'!B$13 -> N3 | C13: ='Giá tháng'!C$13 -> Nhân công nhóm 3 | D13: ='Giá tháng'!D$13 -> công | E13: =HaoPhiVatTu!F$13 -> 1.12 | F13: ='Tổng hợp VT'!O$12 -> 427000 | G13: ='Giá tháng'!G$13 -> 1 | H13: =E13*F13*G13 -> 478240
C14: Cộng | H14: =SUM(H12:H13) -> 678340
C15: c) Máy thi công | H15: =H18 -> 154550.68
B16: ='Giá tháng'!B$15 -> M202.0008 | C16: ='Giá tháng'!C$15 -> Bộ thiết bị siêu âm | D16: ='Giá tháng'!D$15 -> ca | E16: =HaoPhiVatTu!F$15 -> 0.32 | F16: ='Tổng hợp VT'!O$15 -> 478189 | G16: ='Giá tháng'!G$15 -> 1 | H16: =E16*F16*G16 -> 153020.48
B17: M999 | C17: Máy khác | D17: % | E17: =HaoPhiVatTu!F$16 -> 1 | F17: =SUM(H16:H16) -> 153020.48 | H17: =E17*F17/100 -> 1530.2048
C18: Cộng | H18: =SUM(H16:H17) -> 154550.68
A19: =A1 -> ĐƠN GIÁ XÂY DỰNG CHI TIẾT HẠNG MỤC CÔNG TRÌNH
A20: ='Công trình'!A2 -> CÔNG TRÌNH : XÂY DỰNG NHÀ Ở CHO LỰC LƯỢNG VŨ TRANG CÔNG AN NHÂN DÂN (NHÀ Ở XÃ HỘI CHO CÁN BỘ, CHIẾN SỸ CÔNG AN) TẠI CÁC Ô ĐẤT CE-ODK3 VÀ C3-ODK4 THUỘC QUY HOẠCH PHÂN KHU ĐÔ THỊ H2-4, PHƯỜNG YÊN SỞ, THÀNH PHỐ HÀ NỘI
A21: ='Công trình'!F11 -> KHOAN KIỂM TRA XỬ LÝ ĐÁY CỌC KHOAN NHỒI ĐẠI TRÀ
A22: =A4 -> STT | B22: =B4 -> Mã số | C22: =C4 -> Thành phần hao phí | D22: =D4 -> Đơn vị | E22: =E4 -> Định mức | F22: =F4 -> Đơn giá (đ) | G22: =G4 -> Hệ số | H22: =H4 -> Thành tiền (đ)
A23: ='Công trình'!A12 -> 1 | B23: ='Công trình'!E12 -> AL.55120 | C23: ='Công trình'!F12 -> Khoan kiểm tra, xử lý đáy cọc khoan nhồi, đường kính lỗ khoan > 80mm | D23: ='Công trình'!G12 -> cọc | E23: 1
C24: a) Vật liệu | H24: =H27 -> 55160.95
B25: ='Giá tháng'!B$6 -> A24.0247 | C25: ='Giá tháng'!C$6 -> Cần khoan L=1,5m | D25: ='Giá tháng'!D$6 -> cái | E25: =HaoPhiVatTu!F$24 -> 0.026 | F25: ='Tổng hợp VT'!O$23 -> 200000 | G25: ='Giá tháng'!G$6 -> 1 | H25: =E25*F25*G25 -> 5200
B26: ='Giá tháng'!B$7 -> A24.0492 | C26: ='Giá tháng'!C$7 -> Mũi khoan d>80mm | D26: ='Giá tháng'!D$7 -> cái | E26: =HaoPhiVatTu!F$25 -> 0.065 | F26: ='Tổng hợp VT'!O$24 -> 768630 | G26: ='Giá tháng'!G$7 -> 1 | H26: =E26*F26*G26 -> 49960.95
C27: Cộng | H27: =SUM(H25:H26) -> 55160.95
C28: b) Nhân công | H28: =H29 -> 4336500
B29: ='Giá tháng'!B$12 -> N2 | C29: ='Giá tháng'!C$12 -> Nhân công nhóm 2 | D29: ='Giá tháng'!D$12 -> công | E29: =HaoPhiVatTu!F$27 -> 10.5 | F29: ='Tổng hợp VT'!O$27 -> 413000 | G29: ='Giá tháng'!G$12 -> 1 | H29: =E29*F29*G29 -> 4336500
C30: c) Máy thi công | H30: =H34 -> 2186539.6
B31: ='Giá tháng'!B$16 -> M107.0202 | C31: ='Giá tháng'!C$16 -> Máy khoan xoay đập tự hành F105mm | D31: ='Giá tháng'!D$16 -> ca | E31: =HaoPhiVatTu!F$29 -> 0.45 | F31: ='Tổng hợp VT'!O$30 -> 2219339 | G31: ='Giá tháng'!G$16 -> 1 | H31: =E31*F31*G31 -> 998702.55
B32: ='Giá tháng'!B$17 -> M108.0307 | C32: ='Giá tháng'!C$17 -> Máy nén khí diezel 660 m3/h | D32: ='Giá tháng'!D$17 -> ca | E32: =HaoPhiVatTu!F$30 -> 0.45 | F32: ='Tổng hợp VT'!O$31 -> 2408258 | G32: ='Giá tháng'!G$17 -> 1 | H32: =E32*F32*G32 -> 1083716.1
B33: M999 | C33: Máy khác | D33: % | E33: =HaoPhiVatTu!F$31 -> 5 | F33: =SUM(H31:H32) -> 2082418.7 | H33: =E33*F33/100 -> 104120.93
C34: Cộng | H34: =SUM(H31:H33) -> 2186539.6

Sheet TH chi phí XD
A1: BẢNG TỔNG HỢP CHI PHÍ XÂY DỰNG CÔNG TRÌNH
A2: ='Công trình'!A2 -> CÔNG TRÌNH : XÂY DỰNG NHÀ Ở CHO LỰC LƯỢNG VŨ TRANG CÔNG AN NHÂN DÂN (NHÀ Ở XÃ HỘI CHO CÁN BỘ, CHIẾN SỸ CÔNG AN) TẠI CÁC Ô ĐẤT CE-ODK3 VÀ C3-ODK4 THUỘC QUY HOẠCH PHÂN KHU ĐÔ THỊ H2-4, PHƯỜNG YÊN SỞ, THÀNH PHỐ HÀ NỘI
A3: ="Đơn vị tính: "&'Công trình'!AM1 -> Đơn vị tính: (đ)
A4: STT | B4: NỘI DUNG CHI PHÍ | C4: GIÁ TRỊ TRƯỚC THUẾ | D4: THUẾ GTGT | E4: GIÁ TRỊ SAU THUẾ | F4: KÝ HIỆU
A5: 1 | B5: Chi phí xây dựng của công trình chính, phụ trợ | F5: Gxd
A11: 2 | B11: Chi phí nhà tạm để ở và điều hành thi công | F11: Glt
B12: TỔNG CỘNG | C12: =ROUND(C5+C11,0) -> 0 | D12: =ROUND(D5+D11,0) -> 0 | E12: =ROUND(E5+E11,0) -> 0
B13: LÀM TRÒN | E13: =ROUND(E12,-3) -> 0
A14: Bằng chữ: Không đồng chẵn./.

Sheet TH chi phí TB
A1: BẢNG TỔNG HỢP CHI PHÍ THIẾT BỊ CÔNG TRÌNH
A2: ='Công trình'!A2 -> CÔNG TRÌNH : XÂY DỰNG NHÀ Ở CHO LỰC LƯỢNG VŨ TRANG CÔNG AN NHÂN DÂN (NHÀ Ở XÃ HỘI CHO CÁN BỘ, CHIẾN SỸ CÔNG AN) TẠI CÁC Ô ĐẤT CE-ODK3 VÀ C3-ODK4 THUỘC QUY HOẠCH PHÂN KHU ĐÔ THỊ H2-4, PHƯỜNG YÊN SỞ, THÀNH PHỐ HÀ NỘI
A4: STT | B4: Tên thiết bị | C4: Đơn vị | D4: Số lượng | E4: ="Đơn giá trước thuế "&'Công trình'!AM1 -> Đơn giá trước thuế (đ) | F4: ="Thành tiền trước thuế "&'Công trình'!AM1 -> Thành tiền trước thuế (đ) | G4: Thuế VAT | I4: ="Thành tiền sau thuế "&'Công trình'!AM1 -> Thành tiền sau thuế (đ) | J4: Ghi chú, Nguồn gốc xuất xứ
G5: % | H5: ="Thành tiền "&'Công trình'!AM1 -> Thành tiền (đ)
A6: 1 | B6: Chi phí mua sắm thiết bị | F6: =D6*E6 -> 0 | H6: =F6*G6/100 -> 0 | I6: =F6+H6 -> 0
F7: =D7*E7 -> 0 | H7: =F7*G7/100 -> 0 | I7: =F7+H7 -> 0
F8: =D8*E8 -> 0 | H8: =F8*G8/100 -> 0 | I8: =F8+H8 -> 0
F9: =D9*E9 -> 0 | H9: =F9*G9/100 -> 0 | I9: =F9+H9 -> 0
F10: =D10*E10 -> 0 | H10: =F10*G10/100 -> 0 | I10: =F10+H10 -> 0
F11: =D11*E11 -> 0 | H11: =F11*G11/100 -> 0 | I11: =F11+H11 -> 0
F12: =D12*E12 -> 0 | H12: =F12*G12/100 -> 0 | I12: =F12+H12 -> 0
F13: =D13*E13 -> 0 | H13: =F13*G13/100 -> 0 | I13: =F13+H13 -> 0
F14: =D14*E14 -> 0 | H14: =F14*G14/100 -> 0 | I14: =F14+H14 -> 0
F15: =D15*E15 -> 0 | H15: =F15*G15/100 -> 0 | I15: =F15+H15 -> 0
F16: =D16*E16 -> 0 | H16: =F16*G16/100 -> 0 | I16: =F16+H16 -> 0
F17: =D17*E17 -> 0 | H17: =F17*G17/100 -> 0 | I17: =F17+H17 -> 0
F18: =D18*E18 -> 0 | H18: =F18*G18/100 -> 0 | I18: =F18+H18 -> 0
F19: =D19*E19 -> 0 | H19: =F19*G19/100 -> 0 | I19: =F19+H19 -> 0
B20: TỔNG CỘNG | F20: =ROUND(SUM(F6:F19),0) -> 0 | H20: =ROUND(SUM(H6:H19),0) -> 0 | I20: =ROUND(SUM(I6:I19),0) -> 0
A21: Bằng chữ: Không đồng chẵn./.

Sheet HM chung

Sheet Bồi thường
A1: BẢNG TỔNG HỢP CHI PHÍ BỒI THƯỜNG, HỖ TRỢ VÀ TÁI ĐỊNH CƯ
A2: ='Công trình'!A2 -> CÔNG TRÌNH : XÂY DỰNG NHÀ Ở CHO LỰC LƯỢNG VŨ TRANG CÔNG AN NHÂN DÂN (NHÀ Ở XÃ HỘI CHO CÁN BỘ, CHIẾN SỸ CÔNG AN) TẠI CÁC Ô ĐẤT CE-ODK3 VÀ C3-ODK4 THUỘC QUY HOẠCH PHÂN KHU ĐÔ THỊ H2-4, PHƯỜNG YÊN SỞ, THÀNH PHỐ HÀ NỘI
A4: STT | B4: Nội dung công việc | C4: Đơn vị | D4: Số lượng | E4: ="Đơn giá "&'Công trình'!AM1 -> Đơn giá (đ) | F4: Hệ số điều chỉnh | G4: ="Thành tiền "&'Công trình'!AM1 -> Thành tiền (đ) | I4: ="Thành tiền sau thuế "&'Công trình'!AM1 -> Thành tiền sau thuế (đ) | J4: Ghi chú, Nguồn gốc xuất xứ
A6: 1 | B6: Chi phí bồi thường, hỗ trợ và tái định cư | G6: =D6*E6 -> 0
G7: =D7*E7 -> 0
G8: =D8*E8 -> 0
G9: =D9*E9 -> 0
G10: =D10*E10 -> 0
G11: =D11*E11 -> 0
G12: =D12*E12 -> 0
G13: =D13*E13 -> 0
G14: =D14*E14 -> 0
G15: =D15*E15 -> 0
G16: =D16*E16 -> 0
G17: =D17*E17 -> 0
G18: =D18*E18 -> 0
G19: =D19*E19 -> 0
B20: TỔNG CỘNG | G20: =ROUND(SUM(G6:G19),0) -> 0
A21: Bằng chữ: Không đồng chẵn./.

Sheet Dự phòng
A1: ='Công trình'!A2 -> CÔNG TRÌNH : XÂY DỰNG NHÀ Ở CHO LỰC LƯỢNG VŨ TRANG CÔNG AN NHÂN DÂN (NHÀ Ở XÃ HỘI CHO CÁN BỘ, CHIẾN SỸ CÔNG AN) TẠI CÁC Ô ĐẤT CE-ODK3 VÀ C3-ODK4 THUỘC QUY HOẠCH PHÂN KHU ĐÔ THỊ H2-4, PHƯỜNG YÊN SỞ, THÀNH PHỐ HÀ NỘI
A2: CHỈ SỐ GIÁ BÌNH QUÂN
A3: STT | B3: Thời điểm | C3: Chỉ số giá XD | F3: Tỷ lệ ( Isau / Itrước ) | G3: Chỉ số giá XD bình quân
A4: 1 | B4: 2021 | C4: 1.05 | F4: =IF(C4<>0,ROUND(C5/C4,5),0) -> 1 | G4: =ROUND(SUM(F4:F8)/A8,5) -> 1.00952
A5: 2 | B5: 2022 | C5: 1.05 | F5: =IF(C5<>0,ROUND(C6/C5,5),0) -> 1
A6: 3 | B6: 2023 | C6: 1.05 | F6: =IF(C6<>0,ROUND(C7/C6,5),0) -> 1
A7: 4 | B7: 2024 | C7: 1.05 | F7: =IF(C7<>0,ROUND(C8/C7,5),0) -> 1.04762
A8: 5 | B8: 2025 | C8: 1.1 | F8: 1
A10: CHI PHÍ DỰ PHÒNG DO YẾU TỐ TRƯỢT GIÁ
A11: STT | B11: Năm | C11: Vốn phân bổ từng năm | D11: Lãi vay | E11: Chi phí tính dự phòng | F11: Chỉ số giá XD bình quân | G11: Mức biến động chỉ số giá XD | H11: Dự phòng từng năm | I11: Dự phòng lũy kế
C12: ='Công trình'!AM1 -> (đ) | D12: ='Công trình'!AM1 -> (đ) | E12: ='Công trình'!AM1 -> (đ) | H12: ='Công trình'!AM1 -> (đ) | I12: ='Công trình'!AM1 -> (đ)
A13: 1 | B13: 2026 | C13: 733836396 | D13: 0 | E13: =C13-D13 -> 733836396 | F13: =G4 -> 1.00952 | G13: 0.05 | H13: =C13*((F13+G13)^A13-1) -> 43677942 | I13: =H13 -> 43677942
A14: 2 | B14: 2027 | C14: 733836396 | D14: 0 | E14: =C14-D14 -> 733836396 | F14: =G4 -> 1.00952 | G14: 0.05 | H14: =C14*((F14+G14)^A14-1) -> 89955596 | I14: =H14+I13 -> 1.3363354e+08
A15: 3 | B15: 2028 | C15: ='TH kinh phí'!K89-SUM(C13:C14) -> 7.7157151e+08 | D15: 0 | E15: =C15-D15 -> 7.7157151e+08 | F15: =G4 -> 1.00952 | G15: 0.05 | H15: =C15*((F15+G15)^A15-1) -> 1.4613468e+08 | I15: =H15+I14 -> 2.7976822e+08
A16: TỔNG CỘNG | C16: =SUM(C13:C15) -> 2.2392443e+09 | D16: =SUM(D13:D15) -> 0 | E16: =SUM(E13:E15) -> 2.2392443e+09 | H16: =I15 -> 2.7976822e+08

Sheet TH kinh phí
A1: BẢNG TỔNG HỢP DỰ TOÁN CÔNG TRÌNH
A2: Dự án:
A3: Chủ đầu tư/ Cơ quan chuẩn bị dự án:
A4: Tư vấn lập dự án:
A5: Địa điểm XD:
A6: Thời điểm lập dự án:
A7: Thời gian thực hiện dự án:
A8: Nguồn vốn đầu tư: NHÀ NƯỚC
A9: Loại, cấp công trình có cấp cao nhất: 2
A10: ="Đơn vị tính: "&'Công trình'!AM1 -> Đơn vị tính: (đ) | L10: Tổng mức đầu tư
A11: STT | B11: NỘI DUNG CHI PHÍ | C11: Mã số | D11: ĐỊNH MỨC | E11: HỆ SỐ | F11: CÁCH TÍNH | G11: GIÁ TRỊ TRƯỚC THUẾ | H11: THUẾ GTGT | I11: GIÁ TRỊ SAU THUẾ | J11: KÝ HIỆU | K11: 0.1 | L11: Dự kiến | M11: Tiền khả thi | N11: Được duyệt | O11: Ghi chú/ Hướng dẫn
A12: 1 | B12: Chi phí bồi thường, hỗ trợ và tái định cư | C12: Gbttdc | F12: ="" | H12: =ROUND(K11*G12,0) -> 0 | I12: =G12+H12 -> 0 | J12: Gbt,tđc | K12: 1 | O12: Người dùng nhập ở cột Chi phí trước thuế hoặc Tạo và khai báo loại hạng mục "11. Bồi thường, hỗ trợ và tái định cư" bên sheet Công trình
A13: 2 | B13: Chi phí xây dựng | C13: Gxd | F13: ="" | G13: =G14+G15 -> 0 | H13: =H14+H15 -> 0 | I13: =I14+I15 -> 0 | J13: Gcpxd | K13: 1
A14: 2.1 | B14: Chi phí xây dựng công trình chính, phụ trợ tạm phục vụ thi công | C14: Gxdcpt | F14: ="" | G14: ='TH chi phí XD'!C12 -> 0 | H14: ='TH chi phí XD'!D12 -> 0 | I14: =G14+H14 -> 0 | J14: Gxd | K14: =G14+G73 -> 0 | O14: Văn bản số 12637/BXD-KTQLXD ngày 11/08/2026 Bộ XD hướng dẫn: Chi phí xây dựng để tính chi phí QLDA và tư vấn XD là tổng của 3 khoản mục: chi phí trực tiếp (T), chi phí gián tiếp (GT), thu nhập chịu thuế tính trước (TL) và không bao gồm chi phí nhà tạm để ở và điều hành thi công
B15: Chi phí xây dựng nhà tạm tại hiện trường để ở và điều hành thi công | C15: Gxdnt | F15: ="" | J15: Gnt | K15: 1
A16: 3 | B16: Chi phí thiết bị | C16: Gtb | F16: ="" | G16: =G18+G19 -> 0 | H16: =H18+H19 -> 0 | I16: =G16+H16 -> 0 | J16: Gtb | K16: 1 | L16: =G16 -> 0 | M16: =G16 -> 0 | N16: =G16 -> 0 | O16: Người dùng nhập dữ liệu mua sắm, lắp đặt, hiệu chỉnh,... thiết bị ở sheet "TH chi phí TB" hoặc Tạo và khai báo loại hạng mục "7. Lắp đặt, thí nghiệm, hiệu chỉnh, chạy thử thiết bị " bên sheet Công trình
B17: Trong đó : | C17: Gtb_CT | F17: ="" | K17: 1
B18: + Chi phí Mua sắm thiết bị | C18: Gtb_MS | F18: ="" | G18: ='TH chi phí TB'!F20 -> 0 | H18: ='TH chi phí TB'!H20 -> 0 | I18: =G18+H18 -> 0 | K18: 1
B19: + Chi phí lắp đặt, thí nghiệm, hiệu chỉnh, đào tạo và chuyển giao thiết bị | C19: Gtb_LD | F19: ="" | I19: =G19+H19 -> 0 | K19: 1
B20: Phân bổ chi phí thiết bị cho các hạng mục, công trình | C20: Gtb_PB | F20: ="" | K20: 1
B21: Chi phí xây dựng nhà tạm - Phần lắp đặt thiết bị | C21: Gtb_NT | F21: ="" | J21: Gnttb | K21: 1
A22: 4 | B22: Chi phí quản lý dự án | C22: Gqlda | D22: ='Định mức tư vấn'!F3 -> 0.03446 | F22: =D22*100&"% x "&"("&J14&"+"&J16&")" -> 3,446% x (Gxd+Gtb) | G22: =ROUND(D22*(G14+G16),0) -> 0 | H22: =ROUND(K11*G22,0) -> 0 | I22: =G22+H22 -> 0 | J22: Gqlda | K22: 1 | O22: Thông tư 38/2026/TT-BXD
A23: 4 | B23: Chi phí hoạt động của đơn vị quản lý dự án thuộc cơ quan nhà nước có thẩm quyền thực hiện dự án theo hình thức đối tác công tư (PPP) | C23: GqldaPPP | D23: ='Định mức tư vấn'!F4 -> 0.01113 | F23: =D23*100&"% x "&"("&J14&"+"&J16&")" -> 1,113% x (Gxd+Gtb) | G23: =ROUND(D23*(G14+G16),0) -> 0 | H23: =ROUND(K11*G23,0) -> 0 | I23: =G23+H23 -> 0 | J23: Gqlda | K23: 1 | O23: Thông tư 38/2026/TT-BXD
A24: 5 | B24: Chi phí tư vấn đầu tư xây dựng | C24: Gtv | F24: ="" | G24: =SUMIF(K25:K70,1,G25:G70) -> 1.9776403e+09 | H24: =SUMIF(K25:K70,1,H25:H70) -> 1.9776403e+08 | I24: =SUMIF(K25:K70,1,I25:I70) -> 2.1754043e+09 | J24: Gtv | K24: 1
A25: 5.1 | B25: Chi phí khảo sát | C25: Gks | F25: ="" | G25: =SUM(G26:G27) -> 1.8079047e+09 | H25: =SUM(H26:H27) -> 1.8079047e+08 | I25: =SUM(I26:I27) -> 1988695129 | J25: Gtv1 | K25: 1 | O25: Người dùng nhập ở cột Chi phí trước thuế hoặc Tạo và khai báo loại hạng mục "3. Khảo sát" bên sheet Công trình
B26: ="+ "&'Công trình'!F6 -> + THÍ NGHIỆM SIÊU ÂM KIỂM TRA CHẤT LƯỢNG CỌC KHOAN ĐẠI TRÀ | G26: =I26/(1+HSXL!D17) -> 1.5579366e+09 | H26: =I26-G26 -> 1.5579366e+08 | I26: ='THKP hạng mục'!H26 -> 1713730264
B27: ="+ "&'Công trình'!F11 -> + KHOAN KIỂM TRA XỬ LÝ ĐÁY CỌC KHOAN NHỒI ĐẠI TRÀ | G27: =I27/(1+HSXL!D36) -> 2.4996806e+08 | H27: =I27-G27 -> 24996806 | I27: ='THKP hạng mục'!H54 -> 274964865
A28: 5.2 | B28: Chi phí lập nhiệm vụ khảo sát xây dựng | C28: Glnvks | D28: 0.03 | F28: =D28*100&"%*"&C25&IF(E28<>0,"*"&E28,"") -> 3%*Gks | G28: =IF(E28<>0,D28*E28*G25,D28*G25) -> 54237140 | H28: =ROUND(K11*G28,0) -> 5423714 | I28: =G28+H28 -> 59660854 | J28: Gtv2 | K28: 1
A29: 5.3 | B29: Chi phí giám sát công tác khảo sát xây dựng | C29: Ggsks | D29: ='Định mức tư vấn'!F27 -> 0.0396475 | F29: =D29*100&"%*"&C25&IF(E29<>0,"*"&E29,"") -> 3,96475%*Gks | G29: =IF(E29<>0,D29*E29*G25,D29*G25) -> 71678900 | H29: =ROUND(K11*G29,0) -> 7167890 | I29: =G29+H29 -> 78846790 | J29: Gtv3 | K29: 1 | O29: Thông tư 38/2026/TT-BXD
B30: Chi phí lập dự án | C30: Glapda | D30: 0 | F30: ="" | H30: =ROUND(K11*G30,0) -> 0 | J30: Gtv4 | K30: 1 | O30: Thông tư 38/2026/TT-BXD
B31: Chi phí thẩm tra tính hiệu quả và tính khả thi của dự án đầu tư | C31: Ghqkt | D31: 0 | F31: ="" | H31: =ROUND(K11*G31,0) -> 0 | J31: Gtv5 | K31: 1 | O31: Thông tư 38/2026/TT-BXD
A32: 5.4 | B32: Chi phí Lập báo cáo đánh giá tác động môi trường | C32: Gltdmt | F32: ="" | H32: =ROUND(K11*G32,0) -> 0 | I32: =G32+H32 -> 0 | J32: Gtv4 | K32: 1
A33: 5.5 | B33: Chi phí Thẩm định báo cáo đánh giá tác động môi trường (Thông tư 38/2023/TT-BTC) | C33: Gdgtdmt | F33: ="" | G33: ='Định mức tư vấn'!F26 -> 8000000 | H33: =ROUND(K11*G33,0) -> 800000 | I33: =G33+H33 -> 8800000 | J33: Gtv5 | K33: 1 | O33: Thông tư 38/2023/TT-BTC
A34: 5.6 | B34: Chi phí lập báo cáo đề xuất chủ trương đầu tư | C34: Gbcdxctdt | D34: ='Định mức tư vấn'!F5 -> 0.00301 | F34: =D34*100&"% x "&"("&J14&"+"&J16&")" -> 0,301% x (Gxd+Gtb) | G34: =ROUND(D34*(L14+L16),0) -> 0 | H34: =ROUND(K11*G34,0) -> 0 | I34: =G34+H34 -> 0 | J34: Gtv6 | K34: 1 | O34: Thông tư 38/2026/TT-BXD
A35: 5.7 | B35: Chi phí lập báo cáo nghiên cứu tiền khả thi | C35: Gbcnctkt | D35: ='Định mức tư vấn'!F6 -> 0.00668 | F35: =D35*100&"% x "&"("&J14&"+"&J16&")" -> 0,668% x (Gxd+Gtb) | G35: =ROUND(D35*(L14+L16),0) -> 0 | H35: =ROUND(K11*G35,0) -> 0 | I35: =G35+H35 -> 0 | J35: Gtv7 | K35: 1 | O35: Thông tư 38/2026/TT-BXD
A36: 5.8 | B36: Chi phí lập báo cáo nghiên cứu khả thi | C36: Gbcnckt | D36: ='Định mức tư vấn'!F7 -> 0.01114 | F36: =D36*100&"% x "&"("&J14&"+"&J16&")" -> 1,114% x (Gxd+Gtb) | G36: =ROUND(D36*(M14+M16),0) -> 0 | H36: =ROUND(K11*G36,0) -> 0 | I36: =G36+H36 -> 0 | J36: Gtv8 | K36: 1 | O36: Thông tư 38/2026/TT-BXD
A37: 5.9 | B37: Chi phí lập báo cáo kinh tế - kỹ thuật | C37: Gbcktkt | D37: ='Định mức tư vấn'!F11 -> 0.065 | F37: =D37*100&"% x "&"("&J14&"+"&J16&")" -> 6,5% x (Gxd+Gtb) | G37: =ROUND(D37*(L14+L16),0) -> 0 | H37: =ROUND(K11*G37,0) -> 0 | I37: =G37+H37 -> 0 | J37: Gtv9 | K37: 1 | O37: Thông tư 38/2026/TT-BXD
A38: 5.10 | B38: Chi phí thẩm tra báo cáo đề xuất chủ trương đầu tư | C38: Gttbcdxctdt | D38: ='Định mức tư vấn'!F8 -> 0.00071 | F38: =D38*100&"% x "&"("&J14&"+"&J16&")" -> 0,071% x (Gxd+Gtb) | G38: =ROUND(D38*(L14+L16),0) -> 0 | H38: =ROUND(K11*G38,0) -> 0 | I38: =G38+H38 -> 0 | J38: Gtv10 | K38: 1 | O38: Thông tư 38/2026/TT-BXD
A39: 5.11 | B39: Chi phí thẩm tra báo cáo nghiên cứu tiền khả thi | C39: Gttbcnctkt | D39: ='Định mức tư vấn'!F9 -> 0.00071 | F39: =D39*100&"% x "&"("&J14&"+"&J16&")" -> 0,071% x (Gxd+Gtb) | G39: =ROUND(D39*(L14+L16),0) -> 0 | H39: =ROUND(K11*G39,0) -> 0 | I39: =G39+H39 -> 0 | J39: Gtv11 | K39: 1 | O39: Thông tư 38/2026/TT-BXD
A40: 5.12 | B40: Chi phí thẩm tra báo cáo nghiên cứu khả thi | C40: Gttbcnckt | D40: ='Định mức tư vấn'!F10 -> 0.00204 | F40: =D40*100&"% x "&"("&J14&"+"&J16&")" -> 0,204% x (Gxd+Gtb) | G40: =ROUND(D40*(M14+M16),0) -> 0 | H40: =ROUND(K11*G40,0) -> 0 | I40: =G40+H40 -> 0 | J40: Gtv12 | K40: 1 | O40: Thông tư 38/2026/TT-BXD
...

Sheet Chi tiết KL
A1: BẢNG CHI TIẾT KHỐI LƯỢNG CÔNG TÁC XÂY DỰNG
A2: Tên công trình: XÂY DỰNG NHÀ Ở CHO LỰC LƯỢNG VŨ TRANG CÔNG AN NHÂN DÂN (NHÀ Ở XÃ HỘI CHO CÁN BỘ, CHIẾN SỸ CÔNG AN) TẠI CÁC Ô ĐẤT CE-ODK3 VÀ C3-ODK4 THUỘC QUY HOẠCH PHÂN KHU ĐÔ THỊ H2-4, PHƯỜNG YÊN SỞ, THÀNH PHỐ HÀ NỘI
A3: Tên hạng mục: THÍ NGHIỆM SIÊU ÂM KIỂM TRA CHẤT LƯỢNG CỌC KHOAN ĐẠI TRÀ
A4: STT | B4: Ký hiệu bản vẽ | C4: Mã hiệu công tác | D4: Danh mục công tác | E4: Đơn vị tính | F4: Số bộ phận giống nhau | G4: Diễn giải tính toán | H4: Khối lượng một bộ phận | I4: Khối lượng toàn bộ | J4: Ghi chú
A5: (1) | B5: (2) | C5: (3) | D5: (4) | E5: (5) | F5: (6) | G5: (7) | H5: (8) | I5: (9) | J5: (10)
A6: ='Công trình'!A7 -> 1 | B6: ='Công trình'!B7 -> 0 | C6: ='Công trình'!E7 -> CE.12910 | D6: ='Công trình'!F7 -> Thí nghiệm kiểm tra chất lượng cọc bê tông bằng phương pháp siêu âm | E6: ='Công trình'!G7 -> mặt cắt/lần TN | I6: ='Công trình'!P7 -> 1008
F7: ='Công trình'!H8 -> 151 | G7: ='Công trình'!F8&" : "&ROUND('Công trình'!I8,3) -> Cọc D1500 : 6 | H7: =PRODUCT('Công trình'!I8,'Công trình'!J8,'Công trình'!K8,'Công trình'!L8) -> 6 | I7: =ROUND(PRODUCT(F7,H7),3) -> 906
F8: ='Công trình'!H9 -> 34 | G8: ='Công trình'!F9&" : "&ROUND('Công trình'!I9,3) -> Cọc D1000 : 3 | H8: =PRODUCT('Công trình'!I9,'Công trình'!J9,'Công trình'!K9,'Công trình'!L9) -> 3 | I8: =ROUND(PRODUCT(F8,H8),3) -> 102
A9: NGƯỜI LẬP NGƯỜI CHỦ TRÌ
A10: =""
A11: =A1 -> BẢNG CHI TIẾT KHỐI LƯỢNG CÔNG TÁC XÂY DỰNG
A12: =A2 -> Tên công trình: XÂY DỰNG NHÀ Ở CHO LỰC LƯỢNG VŨ TRANG CÔNG AN NHÂN DÂN (NHÀ Ở XÃ HỘI CHO CÁN BỘ, CHIẾN SỸ CÔNG AN) TẠI CÁC Ô ĐẤT CE-ODK3 VÀ C3-ODK4 THUỘC QUY HOẠCH PHÂN KHU ĐÔ THỊ H2-4, PHƯỜNG YÊN SỞ, THÀNH PHỐ HÀ NỘI
A13: Tên hạng mục: KHOAN KIỂM TRA XỬ LÝ ĐÁY CỌC KHOAN NHỒI ĐẠI TRÀ
A14: =A4 -> STT | B14: =B4 -> Ký hiệu bản vẽ | C14: =C4 -> Mã hiệu công tác | D14: =D4 -> Danh mục công tác | E14: =E4 -> Đơn vị tính | F14: =F4 -> Số bộ phận giống nhau | G14: =G4 -> Diễn giải tính toán | H14: =H4 -> Khối lượng một bộ phận | ... J14: =J4 -> Ghi chú
A15: =A5 -> (1) | B15: =B5 -> (2) | C15: =C5 -> (3) | D15: =D5 -> (4) | E15: =E5 -> (5) | F15: =F5 -> (6) | G15: =G5 -> (7) | H15: =H5 -> (8) | ... J15: =J5 -> (10)
A16: ='Công trình'!A12 -> 1 | B16: ='Công trình'!B12 -> 0 | C16: ='Công trình'!E12 -> AL.55120 | D16: ='Công trình'!F12 -> Khoan kiểm tra, xử lý đáy cọc khoan nhồi, đường kính lỗ khoan > 80mm | E16: ='Công trình'!G12 -> cọc | I16: ='Công trình'!P12 -> 22
F17: ='Công trình'!H13 -> 18 | G17: ='Công trình'!F13 -> Cọc D1500 | H17: ='Công trình'!O13 -> 18 | I17: =H17 -> 18
F18: ='Công trình'!H14 -> 4 | G18: ='Công trình'!F14 -> Cọc D1000 | H18: ='Công trình'!O14 -> 4 | I18: =H18 -> 4
A19: NGƯỜI LẬP NGƯỜI CHỦ TRÌ
A20: =""

Sheet Luật XD

Sheet Công trình TL
A1: BẢNG DỰ TOÁN HẠNG MỤC CÔNG TRÌNH
A2: ='Công trình'!A2 -> CÔNG TRÌNH : XÂY DỰNG NHÀ Ở CHO LỰC LƯỢNG VŨ TRANG CÔNG AN NHÂN DÂN (NHÀ Ở XÃ HỘI CHO CÁN BỘ, CHIẾN SỸ CÔNG AN) TẠI CÁC Ô ĐẤT CE-ODK3 VÀ C3-ODK4 THUỘC QUY HOẠCH PHÂN KHU ĐÔ THỊ H2-4, PHƯỜNG YÊN SỞ, THÀNH PHỐ HÀ NỘI
A3: ='Công trình'!F6 -> THÍ NGHIỆM SIÊU ÂM KIỂM TRA CHẤT LƯỢNG CỌC KHOAN ĐẠI TRÀ
A4: TT | B4: Mã số | C4: Tên công tác | D4: Đơn vị | E4: Khối lượng | F4: ="Đơn giá "&'Công trình'!AM1 -> Đơn giá (đ) | K4: ="Thành tiền "&'Công trình'!AM1 -> Thành tiền (đ) | P4: Hệ số điều chỉnh
B5: Đơn giá | F5: Vật liệu | G5: Bù VL | H5: NC XL | I5: NC đất | J5: Ca máy | K5: Vật liệu | L5: Bù VL | M5: NC XL | N5: NC đất | O5: Ca máy | P5: V.L | Q5: N.C | R5: Máy
A6: =A1 -> BẢNG DỰ TOÁN HẠNG MỤC CÔNG TRÌNH
A7: ='Công trình'!A2 -> CÔNG TRÌNH : XÂY DỰNG NHÀ Ở CHO LỰC LƯỢNG VŨ TRANG CÔNG AN NHÂN DÂN (NHÀ Ở XÃ HỘI CHO CÁN BỘ, CHIẾN SỸ CÔNG AN) TẠI CÁC Ô ĐẤT CE-ODK3 VÀ C3-ODK4 THUỘC QUY HOẠCH PHÂN KHU ĐÔ THỊ H2-4, PHƯỜNG YÊN SỞ, THÀNH PHỐ HÀ NỘI
A8: ='Công trình'!F11 -> KHOAN KIỂM TRA XỬ LÝ ĐÁY CỌC KHOAN NHỒI ĐẠI TRÀ
A9: =A4 -> TT | B9: =B4 -> Mã số | C9: =C4 -> Tên công tác | D9: =D4 -> Đơn vị | E9: =E4 -> Khối lượng | F9: =F4 -> Đơn giá (đ) | G9: =G4 -> 0 | H9: =H4 -> 0 | ... R9: =R4 -> 0
A10: =A5 -> 0 | B10: =B5 -> Đơn giá | C10: =C5 -> 0 | D10: =D5 -> 0 | E10: =E5 -> 0 | F10: =F5 -> Vật liệu | G10: =G5 -> Bù VL | H10: =H5 -> NC XL | ... R10: =R5 -> Máy

Sheet Chiết tính
A1: BẢNG CHIẾT TÍNH DỰ THẦU HẠNG MỤC CÔNG TRÌNH
A2: ='Công trình'!A2 -> CÔNG TRÌNH : XÂY DỰNG NHÀ Ở CHO LỰC LƯỢNG VŨ TRANG CÔNG AN NHÂN DÂN (NHÀ Ở XÃ HỘI CHO CÁN BỘ, CHIẾN SỸ CÔNG AN) TẠI CÁC Ô ĐẤT CE-ODK3 VÀ C3-ODK4 THUỘC QUY HOẠCH PHÂN KHU ĐÔ THỊ H2-4, PHƯỜNG YÊN SỞ, THÀNH PHỐ HÀ NỘI
A3: ='Công trình'!F6 -> THÍ NGHIỆM SIÊU ÂM KIỂM TRA CHẤT LƯỢNG CỌC KHOAN ĐẠI TRÀ
A4: STT | B4: Mã số | C4: Thành phần hao phí | D4: Đơn vị | E4: Định mức | F4: ="Đơn giá "&'Công trình'!AM1 -> Đơn giá (đ) | G4: Hệ số | H4: ="Thành tiền "&'Công trình'!AM1 -> Thành tiền (đ)
A5: ='Công trình'!A7 -> 1 | B5: ='Công trình'!E7 -> CE.12910 | C5: ='Công trình'!F7 -> Thí nghiệm kiểm tra chất lượng cọc bê tông bằng phương pháp siêu âm | D5: ='Công trình'!G7 -> mặt cắt/lần TN | E5: 1
C6: a) Vật liệu | H6: =H10 -> 3512.712
B7: ='Giá tháng'!B$9 -> A28.0325 | C7: ='Giá tháng'!C$9 -> Thước thép 5m | D7: ='Giá tháng'!D$9 -> cái | E7: =HaoPhiVatTu!F$8 -> 0.04 | F7: ='Tổng hợp VT'!O$7 -> 13636 | G7: ='Giá tháng'!G$9 -> 1 | H7: =E7*F7*G7 -> 545.44
B8: ='Giá tháng'!B$8 -> A28.0324 | C8: ='Giá tháng'!C$8 -> Thước thép 42m | D8: ='Giá tháng'!D$8 -> cái | E8: =HaoPhiVatTu!F$9 -> 0.04 | F8: ='Tổng hợp VT'!O$6 -> 70000 | G8: ='Giá tháng'!G$8 -> 1 | H8: =E8*F8*G8 -> 2800
B9: Z999 | C9: Vật liệu khác | D9: % | E9: =HaoPhiVatTu!F$10 -> 5 | F9: =SUM(H7:H8) -> 3345.44 | H9: =E9*F9/100 -> 167.272
C10: Cộng | H10: =SUM(H7:H9) -> 3512.712
C11: b) Nhân công | H11: =H14 -> 678340
B12: ='Giá tháng'!B$11 -> NKS | C12: ='Giá tháng'!C$11 -> Kỹ sư | D12: ='Giá tháng'!D$11 -> công | E12: =HaoPhiVatTu!F$12 -> 0.46 | F12: ='Tổng hợp VT'!O$11 -> 435000 | G12: ='Giá tháng'!G$11 -> 1 | H12: =E12*F12*G12 -> 200100
